Workbook

Sheet Executive Summary
A1: FIREWALL RISK ASSESSMENT REPORT | B1: Value | C1: Percentage
A2: FIREWALL RISK ASSESSMENT REPORT
A3: Generated: | B3: 2025-10-27 15:52:54
A5: Total Rules Analyzed:
A6: Average Risk Score: | B6: 1572
A7: Average Risk Score: | B7: 4.4
A9: RISK DISTRIBUTION
A10: High Risk (76+): | B10: 0 | C10: 0.0%
A11: Medium Risk (26-75): | B11: 16 | C11: 1.0%
A12: Low Risk (0-25): | B12: 1556 | C12: 99.0%

Sheet Risk Dashboard
A1: Rule/Level | B1: Details | C1: Score/Count
A2: RISK LEVEL DISTRIBUTION
A3: Critical (90+) | B3: 0 | C3: 0.0%
A4: High (76-89) | B4: 0 | C4: 0.0%
A5: Medium (26-75) | B5: 16 | C5: 1.0%
A6: Low (0-25) | B6: 1556 | C6: 99.0%
A8: TOP 10 RISKIEST RULES
A9: Temp-hMRO Bakken Tower to Tower | C9: 45
A10: Temp-hMRO Eagleford Tower to Tower | C10: 45
A11: Remote Access - OT Machines to Eagleford No UID | C11: 40
A12: Deny - EWS to Web Application JavaScript | C12: 40
A13: GlobalProtect - GPVPN Intercommuncation ports | C13: 35
A14: Claroty - Sites to Eagleford ports | C14: 35
A15: Deny All 3.5 to Internet | C15: 35
A16: Remote Access - OT Machines to Bakken no UID | C16: 30
A17: Remote Access - OT Machines to Eagleford | C17: 30
A18: Remote Access - OT Machines to Delaware Basin Midland N No UID | C18: 30

Sheet Detailed Analysis
A1: Column1 | B1: Column2 | C1: Column3 | D1: Column4 | E1: Column5 | F1: Column6 | G1: Column7 | H1: Column8 | I1: Column9 | J1: Column10 | K1: Column11 | L1: Column12 | M1: Column13 | N1: Column14 | O1: Column15 | P1: Column16 | Q1: Column17 | R1: Column18 | S1: Column19 | T1: Column20 | U1: Column21 | V1: Column22 | W1: Column23 | X1: Column24 | Y1: Column25 | Z1: Column26 | AA1: Column27 | AB1: Column28 | AC1: Column29 | AD1: Column30 | AE1: Column31 | AF1: Column32 | AG1: Column33 | AH1: Column34 | AI1: Column35 | AJ1: Column36 | AK1: Column37 | AL1: Column38 | AM1: Column39 | AN1: Column40 | AO1: Column41 | AP1: Column42 | AQ1: Column43 | AR1: Column44 | AS1: Column45 | AT1: Column46 | AU1: Column47 | AV1: Column48 | AW1: Column49 | AX1: Column50 | AY1: Column51 | AZ1: Column52 | BA1: Column53
A2: [Disabled] bvlotwjump3501.l48ics.net; [Disabled] bvlotwjump3502.l48ics.net; [Disabled] bvlotwjump3503.l48ics.net | B2: [Negate] [Disabled] grp-ConocoPhillips | C2: [Disabled] application-default | D2: [Disabled] ssl; [Disabled] web-browsing | E2: [Disabled] Allow | F2: 0 | G2: Low | H2: otpcnfw-bvl-hoc Policies.csv | I2: [Disabled] Internet Access - Jumpboxes to Internet | J2: otpcnfw-bvl-hoc | K2: [Disabled] none | L2: [Disabled] universal | M2: [Disabled] dmz-remote-access | N2: [Disabled] any | O2: [Disabled] dmz-copent | P2: Profile Group: threat-prevention-only | Q2: Traffic log sent at session end;Log Forwarding Profile setting: Forward to Panorama | R2: Partially Used | S2: [Disabled] INC0015648 INC0022770 INC0041121 INC0044990 INC0046388 INC0046850 INC0062282 INC0081699 INC0059031 INC0060904 INC1145765;[Disabled] Disabled as Jumpboxes do not exist | T2: 18 | U2: 154 | V2: 9/3/2025 10:32 | W2: 2/10/2024 9:58 | AA2: False,0 | AB2: False,0 | AC2: False,0 | AD2: False,0 | AE2: False,0 | AF2: False,0 | AG2: False,0 | AH2: False,0 | AI2: False,0 | AJ2: False,0 | AK2: False,0 | AL2: False,0 | AM2: False,0 | AN2: True,2 | AO2: False,0 | AP2: False,0 | AQ2: False,0 | AR2: False,0 | AS2: False,0 | AT2: 0 | AU2: False,0 | AV2: False,0 | AW2: 0 | AX2: False,0 | AY2: False,0 | BA2: False,0
A3: 172.26.34.12; 172.27.34.12 | B3: 75.2.110.198; 99.83.132.235 | C3: TCP/443 | D3: 22,tcp | E3: Allow | F3: 4 | G3: Low | H3: otpcnfw-bvl-hoc Policies.csv | I3: Internet Access - NetScaler to Alero | J3: otpcnfw-bvl-hoc | K3: none | L3: universal | M3: dmz-nsmgmt | N3: any | O3: dmz-copent | P3: Profile Group: threat-prevention-only | Q3: Traffic log sent at session end;Log Forwarding Profile setting: Forward to Panorama | R3: Partially Used | T3: 2 | U3: 149 | V3: 6/26/2025 11:06 | W3: 2/27/2025 13:28 | AA3: False,0 | AB3: False,0 | AC3: False,0 | AD3: False,0 | AE3: False,0 | AF3: False,0 | AG3: False,0 | AH3: False,0 | AI3: False,0 | AJ3: False,0 | AK3: False,0 | AL3: False,0 | AM3: False,0 | AN3: True,2 | AO3: True,4 | AP3: False,0 | AQ3: False,0 | AR3: False,0 | AS3: False,0 | AT3: 1 | AU3: False,0 | AV3: False,0 | AW3: 1 | AX3: False,0 | AY3: False,0 | BA3: False,0
A4: 172.26.34.12; 172.27.34.12 | B4: [Negate] grp-ConocoPhillips | C4: application-default | D4: 41002,443,tcp; 443,80,tcp; 443,80,9418,tcp; 443,5222-5224,5228,5229,80,tcp; 1080,3128,443,80,8000,8080,tcp; 443,80,8530,8531,tcp; 443,80,8080,tcp; 443,tcp; 3978,444,tcp; 443,444,80,tcp; 28443,443,tcp; 8000,8004,8089,9887,9989,9997,9998,tcp; 22,tcp; 80,tcp; 443,80,8443,tcp | E4: Allow | F4: 4 | G4: Low | H4: otpcnfw-bvl-hoc Policies.csv | I4: Internet Access - Netscaler Proxy to Internet | J4: otpcnfw-bvl-hoc | K4: none | L4: universal | M4: dmz-nsmgmt | N4: any | O4: dmz-copent | P4: Profile Group: threat-prevention-only | Q4: Traffic log sent at session end;Log Forwarding Profile setting: Forward to Panorama | R4: Used | T4: 43 | U4: 1 | V4: 8/7/2025 16:10 | W4: 2/10/2024 9:58 | AA4: False,0 | AB4: False,0 | AC4: False,0 | AD4: False,0 | AE4: False,0 | AF4: False,0 | AG4: False,0 | AH4: False,0 | AI4: False,0 | AJ4: False,0 | AK4: False,0 | AL4: False,0 | AM4: False,0 | AN4: False,0 | AO4: True,4 | AP4: False,0 | AQ4: False,0 | AR4: False,0 | AS4: False,0 | AT4: 0 | AU4: False,0 | AV4: False,0 | AW4: 26 | AX4: False,0 | AY4: False,0 | BA4: False,0
A5: 172.26.34.12; 172.27.34.12 | B5: [Negate] grp-ConocoPhillips | C5: TCP/443 | D5: 22,tcp; 443,tcp | E5: Allow | F5: 4 | G5: Low | H5: otpcnfw-bvl-hoc Policies.csv | I5: Internet Access - Netscaler Proxy to Internet ports | J5: otpcnfw-bvl-hoc | K5: none | L5: universal | M5: dmz-nsmgmt | N5: any | O5: dmz-copent | P5: Profile Group: threat-prevention-only | Q5: Traffic log sent at session end;Log Forwarding Profile setting: Forward to Panorama | R5: Unused | T5: 0 | U5: - | V5: 3/14/2025 7:57 | W5: 6/4/2024 10:57 | AA5: False,0 | AB5: False,0 | AC5: False,0 | AD5: False,0 | AE5: False,0 | AF5: False,0 | AG5: False,0 | AH5: False,0 | AI5: False,0 | AJ5: False,0 | AK5: False,0 | AL5: False,0 | AM5: False,0 | AN5: True,5 | AO5: True,4 | AP5: False,0 | AQ5: False,0 | AR5: False,0 | AS5: False,0 | AT5: 1 | AU5: False,0 | AV5: False,0 | AW5: 2 | AX5: False,0 | AY5: False,0 | BA5: False,0
A6: 172.26.35.4 | B6: [Negate] grp-ConocoPhillips | C6: application-default | D6: 443,80,tcp; 443,80,8530,8531,tcp; 443,tcp | E6: Allow | F6: 4 | G6: Low | H6: otpcnfw-bvl-hoc Policies.csv | I6: Internet Access - WSUS to Microsoft Update | J6: otpcnfw-bvl-hoc | K6: none | L6: universal | M6: dmz-endpoint-protection | N6: any | O6: dmz-copent | P6: Profile Group: threat-prevention-only | Q6: Traffic log sent at session end;Log Forwarding Profile setting: Forward to Panorama | R6: Partially Used | T6: 2 | U6: 10 | V6: 8/14/2025 9:22 | W6: 2/10/2024 9:58 | AA6: False,0 | AB6: False,0 | AC6: False,0 | AD6: False,0 | AE6: False,0 | AF6: False,0 | AG6: False,0 | AH6: False,0 | AI6: False,0 | AJ6: False,0 | AK6: False,0 | AL6: False,0 | AM6: False,0 | AN6: True,2 | AO6: True,4 | AP6: False,0 | AQ6: False,0 | AR6: False,0 | AS6: False,0 | AT6: 0 | AU6: False,0 | AV6: False,0 | AW6: 4 | AX6: False,0 | AY6: False,0 | BA6: False,0
A7: 172.26.33.197 | B7: [Negate] grp-ConocoPhillips | C7: application-default | D7: 443,80,8080,tcp; 443,tcp; 80,tcp | E7: Allow | F7: 4 | G7: Low | H7: otpcnfw-bvl-hoc Policies.csv | I7: Internet Access - OpenShift Bastion to Azure DevOps | J7: otpcnfw-bvl-hoc | K7: none | L7: universal | M7: dmz-automation | N7: any | O7: dmz-copent | P7: Profile Group: threat-prevention-only | Q7: Traffic log sent at session end;Log Forwarding Profile setting: Forward to Panorama | R7: Partially Used | T7: 0 | U7: - | V7: 8/2/2024 4:12 | W7: 2/10/2024 9:58 | AA7: False,0 | AB7: False,0 | AC7: False,0 | AD7: False,0 | AE7: False,0 | AF7: False,0 | AG7: False,0 | AH7: False,0 | AI7: False,0 | AJ7: False,0 | AK7: False,0 | AL7: False,0 | AM7: False,0 | AN7: True,2 | AO7: True,4 | AP7: False,0 | AQ7: False,0 | AR7: False,0 | AS7: False,0 | AT7: 0 | AU7: False,0 | AV7: False,0 | AW7: 3 | AX7: False,0 | AY7: False,0 | BA7: False,0
A8: 172.26.17.135; 172.27.17.136 | B8: [Negate] grp-ConocoPhillips | C8: application-default | D8: 443,80,tcp; 443,tcp | E8: Allow | F8: 4 | G8: Low | H8: otpcnfw-bvl-hoc Policies.csv | I8: Internet Access - Cygnet Snowflake Data | J8: otpcnfw-bvl-hoc | K8: none | L8: universal | M8: dmz-cygnet | N8: any | O8: dmz-copent | P8: Profile Group: threat-prevention-only | Q8: Traffic log sent at session end;Log Forwarding Profile setting: Forward to Panorama | R8: Used | T8: 2 | U8: 10 | V8: 3/14/2025 7:57 | W8: 2/10/2024 9:58 | AA8: False,0 | AB8: False,0 | AC8: False,0 | AD8: False,0 | AE8: False,0 | AF8: False,0 | AG8: False,0 | AH8: False,0 | AI8: False,0 | AJ8: False,0 | AK8: False,0 | AL8: False,0 | AM8: False,0 | AN8: False,0 | AO8: True,4 | AP8: False,0 | AQ8: False,0 | AR8: False,0 | AS8: False,0 | AT8: 0 | AU8: False,0 | AV8: False,0 | AW8: 2 | AX8: False,0 | AY8: False,0 | BA8: False,0
A9: 172.26.17.135; 172.27.17.136 | B9: [Negate] grp-ConocoPhillips | C9: application-default | D9: 443,tcp; 80,tcp | E9: Allow | F9: 4 | G9: Low | H9: otpcnfw-bvl-hoc Policies.csv | I9: Internet Access - Cygnet Weather Data | J9: otpcnfw-bvl-hoc | K9: none | L9: universal | M9: dmz-cygnet | N9: any | O9: dmz-copent | P9: Profile Group: threat-prevention-only | Q9: Traffic log sent at session end;Log Forwarding Profile setting: Forward to Panorama | R9: Used | T9: 1 | U9: 10 | V9: 3/14/2025 7:57 | W9: 2/10/2024 9:58 | AA9: False,0 | AB9: False,0 | AC9: False,0 | AD9: False,0 | AE9: False,0 | AF9: False,0 | AG9: False,0 | AH9: False,0 | AI9: False,0 | AJ9: False,0 | AK9: False,0 | AL9: False,0 | AM9: False,0 | AN9: False,0 | AO9: True,4 | AP9: False,0 | AQ9: False,0 | AR9: False,0 | AS9: False,0 | AT9: 0 | AU9: False,0 | AV9: False,0 | AW9: 2 | AX9: False,0 | AY9: False,0 | BA9: False,0
A10: 172.26.16.5 | B10: [Negate] grp-ConocoPhillips | C10: application-default | D10: 443,tcp | E10: Allow | F10: 4 | G10: Low | H10: otpcnfw-bvl-hoc Policies.csv | I10: Internet Access - Ignition License Gateway to Licensing Portal | J10: otpcnfw-bvl-hoc | K10: none | L10: universal | M10: dmz-ignition-bakken | N10: any | O10: dmz-copent | P10: Profile Group: threat-prevention-only | Q10: Traffic log sent at session end;Log Forwarding Profile setting: Forward to Panorama | R10: Partially Used | T10: 1 | U10: 9 | V10: 3/14/2025 7:57 | W10: 2/10/2024 9:58 | AA10: False,0 | AB10: False,0 | AC10: False,0 | AD10: False,0 | AE10: False,0 | AF10: False,0 | AG10: False,0 | AH10: False,0 | AI10: False,0 | AJ10: False,0 | AK10: False,0 | AL10: False,0 | AM10: False,0 | AN10: True,2 | AO10: True,4 | AP10: False,0 | AQ10: False,0 | AR10: False,0 | AS10: False,0 | AT10: 0 | AU10: False,0 | AV10: False,0 | AW10: 1 | AX10: False,0 | AY10: False,0 | BA10: False,0
A11: 172.26.16.5 | B11: [Negate] grp-ConocoPhillips | C11: application-default | D11: 443,tcp | E11: Allow | F11: 4 | G11: Low | H11: otpcnfw-bvl-hoc Policies.csv | I11: Internet Access - Ignition Snowflake API Query | J11: otpcnfw-bvl-hoc | K11: none | L11: universal | M11: dmz-ignition-bakken | N11: any | O11: dmz-copent | P11: Profile Group: threat-prevention-only | Q11: Traffic log sent at session end;Log Forwarding Profile setting: Forward to Panorama | R11: Partially Used | T11: 0 | U11: - | V11: 3/14/2025 7:57 | W11: 2/10/2024 9:58 | AA11: False,0 | AB11: False,0 | AC11: False,0 | AD11: False,0 | AE11: False,0 | AF11: False,0 | AG11: False,0 | AH11: False,0 | AI11: False,0 | AJ11: False,0 | AK11: False,0 | AL11: False,0 | AM11: False,0 | AN11: True,2 | AO11: True,4 | AP11: False,0 | AQ11: False,0 | AR11: False,0 | AS11: False,0 | AT11: 0 | AU11: False,0 | AV11: False,0 | AW11: 1 | AX11: False,0 | AY11: False,0 | BA11: False,0
A12: 172.26.33.197 | B12: [Negate] grp-ConocoPhillips | C12: application-default | D12: 443,80,tcp; 443,5222-5224,5228,5229,80,tcp; 443,80,8080,tcp; 443,tcp; 80,tcp | E12: Allow | F12: 4 | G12: Low | H12: otpcnfw-bvl-hoc Policies.csv | I12: Internet Access - OpenShift Nodes to Internet | J12: otpcnfw-bvl-hoc | K12: none | L12: universal | M12: dmz-automation;dmz-connprod-mgmt;dmz-remote-access | N12: any | O12: dmz-copent | P12: Profile Group: threat-prevention-only | Q12: Traffic log sent at session end;Log Forwarding Profile setting: Forward to Panorama | R12: Unused | T12: 0 | U12: - | V12: 3/14/2025 7:57 | W12: 2/10/2024 9:58 | AA12: False,0 | AB12: False,0 | AC12: False,0 | AD12: False,0 | AE12: False,0 | AF12: False,0 | AG12: False,0 | AH12: False,0 | AI12: False,0 | AJ12: False,0 | AK12: False,0 | AL12: False,0 | AM12: False,0 | AN12: True,5 | AO12: True,4 | AP12: False,0 | AQ12: False,0 | AR12: False,0 | AS12: False,0 | AT12: 0 | AU12: False,0 | AV12: False,0 | AW12: 8 | AX12: False,0 | AY12: False,0 | BA12: False,0
A13: 172.26.16.5 | B13: [Negate] grp-ConocoPhillips | C13: application-default | D13: 443,80,tcp; 443,tcp; 80,tcp; windows-azure | E13: Allow | F13: 4 | G13: Low | H13: otpcnfw-bvl-hoc Policies.csv | I13: Internet Access - Ignition DMZ Gateway to Azure FileSync | J13: otpcnfw-bvl-hoc | K13: none | L13: universal | M13: dmz-ignition-bakken | N13: any | O13: dmz-copent | P13: Profile Group: threat-prevention-only | Q13: Traffic log sent at session end;Log Forwarding Profile setting: Forward to Panorama | R13: Partially Used | T13: 2 | U13: 9 | V13: 3/14/2025 7:57 | W13: 2/10/2024 9:58 | AA13: False,0 | AB13: False,0 | AC13: False,0 | AD13: False,0 | AE13: False,0 | AF13: False,0 | AG13: False,0 | AH13: False,0 | AI13: False,0 | AJ13: False,0 | AK13: False,0 | AL13: False,0 | AM13: False,0 | AN13: True,2 | AO13: True,4 | AP13: False,0 | AQ13: False,0 | AR13: False,0 | AS13: False,0 | AT13: 0 | AU13: False,0 | AV13: False,0 | AW13: 2 | AX13: False,0 | AY13: False,0 | BA13: False,0
A14: 172.26.9.5; 172.27.9.5 | B14: [Negate] grp-ConocoPhillips | C14: application-default | D14: 443,tcp | E14: Allow | F14: 0 | G14: Low | H14: otpcnfw-bvl-hoc Policies.csv | I14: Internet Access - KMS Licensing to Microsoft | J14: otpcnfw-bvl-hoc | K14: none | L14: universal | M14: dmz-ip-services | N14: any | O14: dmz-copent | P14: Profile Group: threat-prevention-only | Q14: Traffic log sent at session end;Log Forwarding Profile setting: Forward to Panorama | R14: Used | S14: INC0075277 INC0289705 | T14: 1 | U14: 10 | V14: 3/14/2025 7:57 | W14: 2/10/2024 9:58 | AA14: False,0 | AB14: False,0 | AC14: False,0 | AD14: False,0 | AE14: False,0 | AF14: False,0 | AG14: False,0 | AH14: False,0 | AI14: False,0 | AJ14: False,0 | AK14: False,0 | AL14: False,0 | AM14: False,0 | AN14: False,0 | AO14: False,0 | AP14: False,0 | AQ14: False,0 | AR14: False,0 | AS14: False,0 | AT14: 0 | AU14: False,0 | AV14: False,0 | AW14: 1 | AX14: False,0 | AY14: False,0 | BA14: False,0
A15: 172.26.33.199; 172.27.33.197 | B15: [Negate] grp-ConocoPhillips | C15: application-default | D15: 443,80,8080,tcp; 443,tcp; 80,tcp | E15: Allow | F15: 0 | G15: Low | H15: otpcnfw-bvl-hoc Policies.csv | I15: Internet Access - 3.5 Gitlab to AzureDevOps | J15: otpcnfw-bvl-hoc | K15: none | L15: universal | M15: dmz-automation | N15: any | O15: dmz-copent | P15: Profile Group: threat-prevention-only | Q15: Traffic log sent at session end;Log Forwarding Profile setting: Forward to Panorama | R15: Partially Used | S15: INC0227673 | T15: 1 | U15: 10 | V15: 3/19/2025 5:06 | W15: 4/11/2024 10:08 | AA15: False,0 | AB15: False,0 | AC15: False,0 | AD15: False,0 | AE15: False,0 | AF15: False,0 | AG15: False,0 | AH15: False,0 | AI15: False,0 | AJ15: False,0 | AK15: False,0 | AL15: False,0 | AM15: False,0 | AN15: True,2 | AO15: False,0 | AP15: False,0 | AQ15: False,0 | AR15: False,0 | AS15: False,0 | AT15: 0 | AU15: False,0 | AV15: False,0 | AW15: 3 | AX15: False,0 | AY15: False,0 | BA15: False,0
A16: 172.26.17.135; 172.27.17.136 | B16: [Negate] grp-ConocoPhillips | C16: application-default | D16: 443,tcp; 80,tcp | E16: Allow | F16: 0 | G16: Low | H16: otpcnfw-bvl-hoc Policies.csv | I16: Internet Access - Cygnet Qnergy Data | J16: otpcnfw-bvl-hoc | K16: none | L16: universal | M16: dmz-cygnet | N16: any | O16: dmz-copent | P16: Profile Group: threat-prevention-only | Q16: Traffic log sent at session end;Log Forwarding Profile setting: Forward to Panorama | R16: Partially Used | S16: INC0272510 | T16: 1 | U16: 10 | V16: 3/19/2025 5:06 | W16: 5/2/2024 8:58 | AA16: False,0 | AB16: False,0 | AC16: False,0 | AD16: False,0 | AE16: False,0 | AF16: False,0 | AG16: False,0 | AH16: False,0 | AI16: False,0 | AJ16: False,0 | AK16: False,0 | AL16: False,0 | AM16: False,0 | AN16: True,2 | AO16: False,0 | AP16: False,0 | AQ16: False,0 | AR16: False,0 | AS16: False,0 | AT16: 0 | AU16: False,0 | AV16: False,0 | AW16: 2 | AX16: False,0 | AY16: False,0 | BA16: False,0
A17: 172.26.33.199; 172.27.33.197 | B17: [Negate] grp-ConocoPhillips | C17: application-default | D17: 22,443,80,9418,tcp; 443,tcp; 80,tcp | E17: Allow | F17: 0 | G17: Low | H17: otpcnfw-bvl-hoc Policies.csv | I17: Internet Access - 3.5 Gitlab to Github | J17: otpcnfw-bvl-hoc | K17: none | L17: universal | M17: dmz-automation | N17: any | O17: dmz-copent | P17: Profile Group: log-only-threat-prevention | Q17: Traffic log sent at session end;Log Forwarding Profile setting: Forward to Panorama | R17: Partially Used | S17: INC0891905 | T17: 1 | U17: 10 | V17: 4/16/2025 8:58 | W17: 4/14/2025 8:00 | AA17: False,0 | AB17: False,0 | AC17: False,0 | AD17: False,0 | AE17: False,0 | AF17: False,0 | AG17: False,0 | AH17: False,0 | AI17: False,0 | AJ17: False,0 | AK17: False,0 | AL17: False,0 | AM17: False,0 | AN17: True,2 | AO17: False,0 | AP17: False,0 | AQ17: False,0 | AR17: False,0 | AS17: False,0 | AT17: 0 | AU17: False,0 | AV17: False,0 | AW17: 4 | AX17: False,0 | AY17: False,0 | BA17: False,0
A18: 172.26.35.132; 172.27.35.132 | B18: [Negate] grp-ConocoPhillips | C18: application-default | D18: 443,tcp | E18: Allow | F18: 0 | G18: Low | H18: otpcnfw-bvl-hoc Policies.csv | I18: Internet Access - 3.5 Nozomi to Nozomi S3 Bucket | J18: otpcnfw-bvl-hoc | K18: none | L18: universal | M18: dmz-nozomi | N18: any | O18: dmz-copent | P18: Profile Group: threat-prevention-only | Q18: Traffic log sent at session end;Log Forwarding Profile setting: Forward to Panorama | R18: Used | S18: INC0927276 INC0990598;May be temporary 5/5 | T18: 1 | U18: 10 | V18: 6/24/2025 9:16 | W18: 5/5/2025 10:00 | AA18: False,0 | AB18: False,0 | AC18: False,0 | AD18: False,0 | AE18: False,0 | AF18: False,0 | AG18: False,0 | AH18: False,0 | AI18: False,0 | AJ18: False,0 | AK18: False,0 | AL18: False,0 | AM18: False,0 | AN18: False,0 | AO18: False,0 | AP18: False,0 | AQ18: False,0 | AR18: False,0 | AS18: False,0 | AT18: 0 | AU18: False,0 | AV18: False,0 | AW18: 1 | AX18: False,0 | AY18: False,0 | BA18: False,0
A19: [Disabled] grp-ConocoPhillips | B19: [Disabled] grp-all-jumpboxes | C19: [Disabled] application-default | D19: [Disabled] ms-rdp; [Disabled] ping; [Disabled] ssh; [Disabled] ssl | E19: [Disabled] Allow | F19: 0 | G19: Low | H19: otpcnfw-bvl-hoc Policies.csv | I19: [Disabled] 4.0 to 3.5 - RDP to DMZ Jumpboxes | J19: otpcnfw-bvl-hoc | K19: [Disabled] INC-Verified | L19: [Disabled] universal | M19: [Disabled] dmz-copent | N19: [Disabled] any | O19: [Disabled] dmz-remote-access | P19: Profile Group: threat-prevention-only | Q19: Traffic log sent at session end;Log Forwarding Profile setting: Forward to Panorama | R19: - | S19: [Disabled] INC0051565 INC0283774 INC0513837 INC0769904 | T19: 0 | U19: - | V19: 2/4/2025 17:16 | W19: 2/10/2024 9:58 | AA19: False,0 | AB19: False,0 | AC19: False,0 | AD19: False,0 | AE19: False,0 | AF19: False,0 | AG19: False,0 | AH19: False,0 | AI19: False,0 | AJ19: False,0 | AK19: False,0 | AL19: False,0 | AM19: False,0 | AN19: True,5 | AO19: False,0 | AP19: False,0 | AQ19: False,0 | AR19: False,0 | AS19: False,0 | AT19: 0 | AU19: False,0 | AV19: False,0 | AW19: 0 | AX19: False,0 | AY19: False,0 | BA19: False,0
A20: [Disabled] grp-ConocoPhillips | B20: [Disabled] bvlotwjump3501.l48ics.net | C20: [Disabled] application-default | D20: [Disabled] ms-rdp; [Disabled] ping; [Disabled] ssh; [Disabled] ssl | E20: [Disabled] Allow | F20: 0 | G20: Low | H20: otpcnfw-bvl-hoc Policies.csv | I20: [Disabled] 4.0 to 3.5 - RDP to DMZ Jumpbox Breakglass | J20: otpcnfw-bvl-hoc | K20: [Disabled] INC-Verified | L20: [Disabled] universal | M20: [Disabled] dmz-copent | N20: [Disabled] any | O20: [Disabled] dmz-remote-access | P20: Profile Group: threat-prevention-only | Q20: Traffic log sent at session end;Log Forwarding Profile setting: Forward to Panorama | R20: - | S20: [Disabled] INC0769904 | T20: 0 | U20: - | V20: 2/5/2025 8:32 | W20: 2/4/2025 17:16 | AA20: False,0 | AB20: False,0 | AC20: False,0 | AD20: False,0 | AE20: False,0 | AF20: False,0 | AG20: False,0 | AH20: False,0 | AI20: False,0 | AJ20: False,0 | AK20: False,0 | AL20: False,0 | AM20: False,0 | AN20: True,5 | AO20: False,0 | AP20: False,0 | AQ20: False,0 | AR20: False,0 | AS20: False,0 | AT20: 0 | AU20: False,0 | AV20: False,0 | AW20: 0 | AX20: False,0 | AY20: False,0 | BA20: False,0
A21: [Disabled] grp-ConocoPhillips | B21: [Disabled] bvlotujump3501.l48ics.net | C21: [Disabled] application-default | D21: [Disabled] ms-rdp; [Disabled] ping; [Disabled] ssh; [Disabled] ssl | E21: [Disabled] Allow | F21: 0 | G21: Low | H21: otpcnfw-bvl-hoc Policies.csv | I21: [Disabled] 4.0 to 3.5 - RDP to DMZ Jumpbox | J21: otpcnfw-bvl-hoc | K21: [Disabled] INC-Verified | L21: [Disabled] universal | M21: [Disabled] dmz-copent | N21: [Disabled] any | O21: [Disabled] dmz-remote-access | P21: Profile Group: threat-prevention-only | Q21: Traffic log sent at session end;Log Forwarding Profile setting: Forward to Panorama | R21: - | S21: [Disabled] INC0774791 | T21: 0 | U21: - | V21: 2/5/2025 14:13 | W21: 2/5/2025 8:28 | AA21: False,0 | AB21: False,0 | AC21: False,0 | AD21: False,0 | AE21: False,0 | AF21: False,0 | AG21: False,0 | AH21: False,0 | AI21: False,0 | AJ21: False,0 | AK21: False,0 | AL21: False,0 | AM21: False,0 | AN21: True,5 | AO21: False,0 | AP21: False,0 | AQ21: False,0 | AR21: False,0 | AS21: False,0 | AT21: 0 | AU21: False,0 | AV21: False,0 | AW21: 0 | AX21: False,0 | AY21: False,0 | BA21: False,0
A22: 10.0.0.0/8; 138.32.0.0/16; 153.15.0.0/16; 155.191.0.0/16; 158.139.0.0/16; 159.163.0.0/16; 172.16.0.0/12; 192.168.0.0/16 | B22: 172.26.36.100; 172.26.36.104; 172.26.36.20 | C22: application-default | D22: 22,tcp; 443,tcp | E22: Allow | F22: 10 | G22: Low | H22: otpcnfw-bvl-hoc Policies.csv | I22: 4.0 to 3.5 - SRA - Enterprise to Claroty 3.5 Central | J22: otpcnfw-bvl-hoc | K22: none | L22: universal | M22: dmz-copent | N22: any | O22: dmz-remote-access | P22: Profile Group: threat-prevention-only | Q22: Traffic log sent at session end;Log Forwarding Profile setting: Forward to Panorama | R22: Partially Used | S22: INC7114688 INC0287933 | T22: 1 | U22: 1 | V22: 3/19/2025 5:06 | W22: 2/10/2024 9:58 | AA22: False,0 | AB22: True,10 | AC22: False,0 | AD22: False,0 | AE22: False,0 | AF22: False,0 | AG22: False,0 | AH22: False,0 | AI22: False,0 | AJ22: False,0 | AK22: False,0 | AL22: False,0 | AM22: False,0 | AN22: True,2 | AO22: False,0 | AP22: False,0 | AQ22: False,0 | AR22: False,0 | AS22: False,0 | AT22: 0 | AU22: False,0 | AV22: False,0 | AW22: 2 | AX22: False,0 | AY22: False,0 | BA22: False,0
A23: 10.0.0.0/8; 138.32.0.0/16; 153.15.0.0/16; 155.191.0.0/16; 158.139.0.0/16; 159.163.0.0/16; 172.16.0.0/12; 192.168.0.0/16 | B23: 172.26.32.110; 172.26.32.111; 172.26.32.112; 172.26.32.113; 172.26.32.114; 172.26.39.5; 172.26.39.6; 172.26.39.9; 172.26.7.12; 172.26.7.5; 172.26.7.9; 172.27.32.100; 172.27.32.101; 172.27.32.104; 172.27.7.4; 172.27.7.6 | C23: TCP/443; TCP/3389 | D23: 3389,tcp,udp; 443,tcp; 80,tcp | E23: Allow | F23: 15 | G23: Low | H23: otpcnfw-bvl-hoc Policies.csv | I23: 4.0 to 3.5 - CyberArk to PVWA Servers | J23: otpcnfw-bvl-hoc | K23: none | L23: universal | M23: dmz-copent | N23: any | O23: dmz-centralsvc-nonprod;dmz-cyberark;dmz-nsext | P23: Profile Group: threat-prevention-only | Q23: Traffic log sent at session end;Log Forwarding Profile setting: Forward to Panorama | R23: Partially Used | S23: INC0172168 INC0221328 | T23: 3 | U23: 4 | V23: 3/19/2025 5:06 | W23: 3/5/2024 16:40 | AA23: False,0 | AB23: True,10 | AC23: False,0 | AD23: False,0 | AE23: False,0 | AF23: False,0 | AG23: False,0 | AH23: False,0 | AI23: False,0 | AJ23: False,0 | AK23: True,5 | AL23: False,0 | AM23: False,0 | AN23: True,2 | AO23: False,0 | AP23: False,0 | AQ23: False,0 | AR23: False,0 | AS23: False,0 | AT23: 2 | AU23: False,0 | AV23: False,0 | AW23: 3 | AX23: False,0 | AY23: False,0 | AZ23: mocha-rdp | BA23: True,10
A24: 10.0.0.0/8; 138.32.0.0/16; 153.15.0.0/16; 155.191.0.0/16; 158.139.0.0/16; 159.163.0.0/16; 172.16.0.0/12; 192.168.0.0/16 | B24: 172.26.19.7; 172.26.7.18; 172.27.7.13; 172.26.7.22; 172.27.7.22; 172.26.39.12; 172.27.39.3; 172.26.34.12; 172.27.34.12 | C24: TCP/443; TCP/8443 | D24: 443,tcp | E24: Allow | F24: 10 | G24: Low | H24: otpcnfw-bvl-hoc Policies.csv | I24: 4.0 to 3.5 - Enterprise to ForgeRock LTMs | J24: otpcnfw-bvl-hoc | K24: none | L24: universal | M24: dmz-copent | N24: any | O24: dmz-centralsvc-nonprod;dmz-forgerock;dmz-nsext | P24: Profile Group: threat-prevention-only | Q24: Traffic log sent at session end;Log Forwarding Profile setting: Forward to Panorama | R24: Partially Used | S24: INC0207623 INC0225572 INC0279123 INC1145754 | T24: 1 | U24: 10 | V24: 9/2/2025 12:04 | W24: 4/1/2024 12:18 | AA24: False,0 | AB24: True,10 | AC24: False,0 | AD24: False,0 | AE24: False,0 | AF24: False,0 | AG24: False,0 | AH24: False,0 | AI24: False,0 | AJ24: False,0 | AK24: False,0 | AL24: False,0 | AM24: False,0 | AN24: True,2 | AO24: False,0 | AP24: False,0 | AQ24: False,0 | AR24: False,0 | AS24: False,0 | AT24: 2 | AU24: False,0 | AV24: False,0 | AW24: 1 | AX24: False,0 | AY24: False,0 | BA24: False,0
A25: [Disabled] grp-ConocoPhillips | B25: [Disabled] grp-dmz-netscaler-adns | C25: [Disabled] application-default | D25: [Disabled] dns-base | E25: [Disabled] Allow | F25: 0 | G25: Low | H25: otpcnfw-bvl-hoc Policies.csv | I25: [Disabled] 4.0 to 3.5 - NetScaler GSLB 4.0 DNS Traffic | J25: otpcnfw-bvl-hoc | K25: [Disabled] none | L25: [Disabled] universal | M25: [Disabled] dmz-copent | N25: [Disabled] any | O25: [Disabled] dmz-nsext | P25: Profile Group: threat-prevention-only | Q25: Traffic log sent at session end;Log Forwarding Profile setting: Forward to Panorama | R25: Unused | S25: [Disabled] INC0150524 | T25: 0 | U25: - | V25: 7/23/2025 15:41 | W25: 2/26/2024 12:09 | AA25: False,0 | AB25: False,0 | AC25: False,0 | AD25: False,0 | AE25: False,0 | AF25: False,0 | AG25: False,0 | AH25: False,0 | AI25: False,0 | AJ25: False,0 | AK25: False,0 | AL25: False,0 | AM25: False,0 | AN25: True,5 | AO25: False,0 | AP25: False,0 | AQ25: False,0 | AR25: False,0 | AS25: False,0 | AT25: 0 | AU25: False,0 | AV25: False,0 | AW25: 0 | AX25: False,0 | AY25: False,0 | BA25: False,0
A26: 10.0.0.0/8; 138.32.0.0/16; 153.15.0.0/16; 155.191.0.0/16; 158.139.0.0/16; 159.163.0.0/16; 172.16.0.0/12; 192.168.0.0/16 | B26: 172.26.37.10; 172.27.37.8 | C26: application-default | D26: 22,tcp; 443,tcp | E26: Allow | F26: 10 | G26: Low | H26: otpcnfw-bvl-hoc Policies.csv | I26: 4.0 to 3.5 - Enterprise to DMZ SFTP Servers | J26: otpcnfw-bvl-hoc | K26: none | L26: universal | M26: dmz-copent | N26: any | O26: dmz-file-share | P26: Profile Group: threat-prevention-only | Q26: Traffic log sent at session end;Log Forwarding Profile setting: Forward to Panorama | R26: Partially Used | S26: INC0051565 INC0119422 INC0719466 INC1145754 | T26: 2 | U26: 10 | V26: 9/2/2025 12:04 | W26: 2/10/2024 9:58 | AA26: False,0 | AB26: True,10 | AC26: False,0 | AD26: False,0 | AE26: False,0 | AF26: False,0 | AG26: False,0 | AH26: False,0 | AI26: False,0 | AJ26: False,0 | AK26: False,0 | AL26: False,0 | AM26: False,0 | AN26: True,2 | AO26: False,0 | AP26: False,0 | AQ26: False,0 | AR26: False,0 | AS26: False,0 | AT26: 0 | AU26: False,0 | AV26: False,0 | AW26: 2 | AX26: False,0 | AY26: False,0 | BA26: False,0
A27: 10.113.244.14; 10.113.244.15; 10.113.248.14; 10.113.248.15; 10.113.252.14; 10.162.72.10; 10.164.19.75; 10.201.160.15; 10.201.160.16; 10.201.164.14; 10.201.164.15; 10.201.168.11; 10.235.0.24; 10.235.0.25; 10.235.12.11; 10.235.16.11; 10.235.20.11; 10.235.4.21; 10.235.4.22; 10.235.8.20; 10.246.132.14; 10.246.132.15; 10.246.136.14; 10.246.136.15; 10.246.140.11; 10.25.52.31; 10.25.52.8; 10.26.15.30; 10.26.15.40; 10.77.244.12; 153.15.10.100; 153.15.150.235; 153.15.164.164; 153.15.34.61; 153.15.65.220; 155.191.182.135; 155.191.182.136; 158.139.110.76; 158.139.137.12; 158.139.137.238; 158.139.137.45; 158.139.145.21; 158.139.192.200; 158.139.192.202; 158.139.212.31; 158.139.213.59; 158.139.221.60; 158.139.44.10; 158.139.44.36; 158.139.73.23; 159.163.178.5; 159.163.188.17; 159.163.244.5; 159.163.254.12; 159.163.76.47; 159.163.89.130; 164.123.209.137; 164.123.209.197; 164.123.209.72; 164.123.209.8; 164.123.210.12 | B27: 172.26.9.6; 172.27.9.6 | C27: application-default | D27: 53,5353,tcp,udp | E27: Allow | F27: 0 | G27: Low | H27: otpcnfw-bvl-hoc Policies.csv | I27: 4.0 to 3.5 - DNS Queries to 3.5 DNS Servers | J27: otpcnfw-bvl-hoc | K27: none | L27: universal | M27: dmz-copent | N27: any | O27: dmz-ip-services | P27: Profile Group: threat-prevention-only | Q27: Traffic log sent at session end;Log Forwarding Profile setting: Forward to Panorama | R27: Used | S27: INC0160717 INC0204522 | T27: 1 | U27: 10 | V27: 3/19/2025 5:06 | W27: 2/28/2024 12:36 | AA27: False,0 | AB27: False,0 | AC27: False,0 | AD27: False,0 | AE27: False,0 | AF27: False,0 | AG27: False,0 | AH27: False,0 | AI27: False,0 | AJ27: False,0 | AK27: False,0 | AL27: False,0 | AM27: False,0 | AN27: False,0 | AO27: False,0 | AP27: False,0 | AQ27: False,0 | AR27: False,0 | AS27: False,0 | AT27: 0 | AU27: False,0 | AV27: False,0 | AW27: 2 | AX27: False,0 | AY27: False,0 | BA27: False,0
A28: 10.0.0.0/8; 138.32.0.0/16; 153.15.0.0/16; 155.191.0.0/16; 158.139.0.0/16; 159.163.0.0/16; 172.16.0.0/12; 192.168.0.0/16 | B28: 172.26.7.8; 172.27.7.14; 172.27.7.8 | C28: application-default | D28: dynamic,udp; 443,tcp; 80,tcp | E28: Allow | F28: 10 | G28: Low | H28: otpcnfw-bvl-hoc Policies.csv | I28: 4.0 to 3.5 - Enterprise to NetScaler Gateway vServer | J28: otpcnfw-bvl-hoc | K28: none | L28: universal | M28: dmz-copent | N28: any | O28: dmz-nsext | P28: Profile Group: threat-prevention-only | Q28: Traffic log sent at session end;Log Forwarding Profile setting: Forward to Panorama | R28: Partially Used | S28: INC0150524 INC0569558 | T28: 2 | U28: 1 | V28: 3/19/2025 5:06 | W28: 2/22/2024 11:40 | AA28: False,0 | AB28: True,10 | AC28: False,0 | AD28: False,0 | AE28: False,0 | AF28: False,0 | AG28: False,0 | AH28: False,0 | AI28: False,0 | AJ28: False,0 | AK28: False,0 | AL28: False,0 | AM28: False,0 | AN28: True,2 | AO28: False,0 | AP28: False,0 | AQ28: False,0 | AR28: False,0 | AS28: False,0 | AT28: 0 | AU28: False,0 | AV28: False,0 | AW28: 2 | AX28: False,0 | AY28: False,0 | BA28: False,0
A29: 158.139.128.53 | B29: 172.26.37.10; 172.27.37.8; 172.26.37.4 | C29: application-default | D29: 22,tcp | E29: Allow | F29: 0 | G29: Low | H29: otpcnfw-bvl-hoc Policies.csv | I29: 4.0 to 3.5 - Cygnet data from COP Enterprise | J29: otpcnfw-bvl-hoc | K29: none | L29: universal | M29: dmz-copent | N29: any | O29: dmz-cygnet;dmz-file-share | P29: Profile Group: threat-prevention-only | Q29: Traffic log sent at session end;Log Forwarding Profile setting: Forward to Panorama | R29: Unused | S29: INC0116679 INC0719466 | T29: 0 | U29: - | V29: 3/19/2025 5:06 | W29: 2/10/2024 9:58 | AA29: False,0 | AB29: False,0 | AC29: False,0 | AD29: False,0 | AE29: False,0 | AF29: False,0 | AG29: False,0 | AH29: False,0 | AI29: False,0 | AJ29: False,0 | AK29: False,0 | AL29: False,0 | AM29: False,0 | AN29: True,5 | AO29: False,0 | AP29: False,0 | AQ29: False,0 | AR29: False,0 | AS29: False,0 | AT29: 0 | AU29: False,0 | AV29: False,0 | AW29: 1 | AX29: False,0 | AY29: False,0 | BA29: False,0
A30: 172.28.126.0/24 | B30: 172.26.37.10; 172.27.37.8 | C30: application-default | D30: 22,tcp; 443,tcp | E30: Allow | F30: 0 | G30: Low | H30: otpcnfw-bvl-hoc Policies.csv | I30: 3.0 to 3.5 - OT Lab to 3.5 SFTP | J30: otpcnfw-bvl-hoc | K30: none | L30: universal | M30: zone-to-branch | N30: any | O30: dmz-file-share | P30: Profile Group: threat-prevention-only | Q30: Traffic log sent at session end;Log Forwarding Profile setting: Forward to Panorama | R30: Partially Used | S30: RITM0178715 | T30: 0 | U30: - | V30: 7/22/2025 15:50 | W30: 7/17/2025 9:45 | AA30: False,0 | AB30: False,0 | AC30: False,0 | AD30: False,0 | AE30: False,0 | AF30: False,0 | AG30: False,0 | AH30: False,0 | AI30: False,0 | AJ30: False,0 | AK30: False,0 | AL30: False,0 | AM30: False,0 | AN30: True,2 | AO30: False,0 | AP30: False,0 | AQ30: False,0 | AR30: False,0 | AS30: False,0 | AT30: 0 | AU30: False,0 | AV30: False,0 | AW30: 2 | AX30: False,0 | AY30: False,0 | BA30: False,0
A31: 158.139.121.193; 158.139.121.194; 158.139.121.196; 158.139.128.195; 158.139.128.204; 158.139.128.53; 158.139.129.119; 158.139.129.121; 158.139.129.124; 158.139.129.128; 158.139.129.141; 158.139.129.144; 158.139.129.145; 158.139.129.147; 159.139.121.195; 158.139.110.113; 158.139.110.135; 158.139.110.232; 158.139.110.233; 158.139.110.236; 158.139.110.238; 158.139.110.243; 158.139.110.246; 158.139.110.247; 158.139.110.248; 158.139.110.251; 158.139.110.252; 158.139.110.255; 158.139.111.0 | B31: 172.26.17.140; 172.26.17.141; 172.26.17.142; 172.26.17.143; 172.26.17.144; 172.26.17.145; 172.26.17.146; 172.26.17.147; 172.26.17.148; 172.26.17.149; 172.26.17.150; 172.26.17.161; 172.27.17.155; 172.27.17.157; 172.27.17.158; 172.27.17.159; 172.27.17.160; 172.27.17.161; 172.27.17.162; 172.27.17.163; 172.27.17.164; 172.27.17.165; 172.27.17.166; 172.27.17.167; 172.27.17.168 | C31: UDP/6000-6100; UDP/8834; UDP/9834 | D31: dynamic,udp | E31: Allow | F31: 0 | G31: Low | H31: otpcnfw-bvl-hoc Policies.csv | I31: 4.0 to 3.5 - Cygnet ENT to Cygnet DMZ servers | J31: otpcnfw-bvl-hoc | K31: none | L31: universal | M31: dmz-copent | N31: any | O31: dmz-cygnet | P31: Profile Group: threat-prevention-only | Q31: Traffic log sent at session end;Log Forwarding Profile setting: Forward to Panorama | R31: Used | S31: INC0071646 INC0312813 | T31: 1 | U31: 1 | V31: 3/19/2025 5:06 | W31: 2/10/2024 9:58 | AA31: False,0 | AB31: False,0 | AC31: False,0 | AD31: False,0 | AE31: False,0 | AF31: False,0 | AG31: False,0 | AH31: False,0 | AI31: False,0 | AJ31: False,0 | AK31: False,0 | AL31: False,0 | AM31: False,0 | AN31: False,0 | AO31: False,0 | AP31: False,0 | AQ31: False,0 | AR31: False,0 | AS31: False,0 | AT31: 103 | AU31: False,0 | AV31: False,0 | AW31: 0 | AX31: False,0 | AY31: False,0 | BA31: False,0
A32: 158.139.136.128; 158.139.136.154; 158.139.136.155; 158.139.136.157; 158.139.136.163; 158.139.136.87; 158.139.137.197; 158.139.137.91; 158.139.222.9; 158.139.233.11; 158.139.233.144; 158.139.233.34; 158.139.102.118; 158.139.102.155; 158.139.102.156; 158.139.102.179; 158.139.136.112; 158.139.136.118; 158.139.137.169; 158.139.137.170; 158.139.137.211; 158.139.137.228; 158.139.137.231; 158.139.174.145; 158.139.174.160; 158.139.233.175; 158.139.136.125; 158.139.136.172; 158.139.136.176; 158.139.136.177; 158.139.136.6; 158.139.137.191; 158.139.137.47; 158.139.233.115; 158.139.137.187; 158.139.167.215; 158.139.167.216; 158.139.222.50 | B32: 172.26.6.10; 172.26.6.11; 172.26.6.12; 172.26.6.16; 172.26.6.18; 172.26.6.14; 172.26.6.15; 172.26.6.17; 172.26.6.19; 172.26.6.7; 172.26.6.108; 172.26.6.13; 172.26.6.8 | C32: TCP/22; TCP/8083; TCP/8090; TCP/9091-9096; TCP/30000-30010 | D32: any | E32: Allow | F32: 10 | G32: Low | H32: otpcnfw-bvl-hoc Policies.csv | I32: 4.0 to 3.5 - 4.0 Kafka Servers to 3.5 Kafka Proxy | J32: otpcnfw-bvl-hoc | K32: Unknown-TCP/UDP | L32: universal | M32: dmz-copent | N32: any | O32: dmz-streaming | P32: Profile Group: threat-prevention-only | Q32: Traffic log sent at session end;Log Forwarding Profile setting: Forward to Panorama | R32: Partially Used | S32: INC0493929 INC0876370 INC0891410 INC1087363 | T32: 1 | U32: 95 | V32: 7/28/2025 8:20 | W32: 8/21/2024 14:22 | AA32: False,0 | AB32: False,0 | AC32: False,0 | AD32: False,0 | AE32: False,0 | AF32: False,0 | AG32: False,0 | AH32: False,0 | AI32: False,0 | AJ32: True,10 | AK32: False,0 | AL32: False,0 | AM32: False,0 | AN32: True,2 | AO32: False,0 | AP32: False,0 | AQ32: False,0 | AR32: False,0 | AS32: False,0 | AT32: 20 | AU32: False,0 | AV32: True,0 | AW32: 65535 | AX32: True,0 | AY32: False,0 | BA32: False,0
A33: [Disabled] hocuapp0218.conocophillips.net; [Disabled] hocuapp0219.conocophillips.net | B33: [Disabled] hocdmzupxdr001.l48ics.net | C33: [Disabled] tcp-8083; [Disabled] tcp-30001-30010 | D33: [Disabled] ssl | E33: [Disabled] Allow | F33: 0 | G33: Low | H33: otpcnfw-bvl-hoc Policies.csv | I33: [Disabled] 4.0 to 3.5 - Kafka - Houston Enterprise DR to 3.5 DR | J33: otpcnfw-bvl-hoc | K33: [Disabled] INC-Verified | L33: [Disabled] universal | M33: [Disabled] dmz-copent | N33: [Disabled] any | O33: [Disabled] dmz-streaming | P33: Profile Group: threat-prevention-only | Q33: Traffic log sent at session end;Log Forwarding Profile setting: Forward to Panorama | R33: - | S33: [Disabled] INC0357035 | T33: 0 | U33: - | V33: 9/11/2024 13:49 | W33: 6/19/2024 9:53 | AA33: False,0 | AB33: False,0 | AC33: False,0 | AD33: False,0 | AE33: False,0 | AF33: False,0 | AG33: False,0 | AH33: False,0 | AI33: False,0 | AJ33: False,0 | AK33: False,0 | AL33: False,0 | AM33: False,0 | AN33: True,5 | AO33: False,0 | AP33: False,0 | AQ33: False,0 | AR33: False,0 | AS33: False,0 | AT33: 0 | AU33: False,0 | AV33: False,0 | AW33: 0 | AX33: False,0 | AY33: False,0 | BA33: False,0
A34: grp-enterprise-hoc-kafka-brokers | B34: hocdmzupxp004.l48ics.net; hocdmzupxp005.l48ics.net | C34: TCP/30001-30010 | D34: 443,tcp | E34: Allow | F34: 0 | G34: Low | H34: otpcnfw-bvl-hoc Policies.csv | I34: 4.0 to 3.5 - Kafka Houston Enterprise Brokers to 3.5 Proxy | J34: otpcnfw-bvl-hoc | K34: none | L34: universal | M34: dmz-copent | N34: any | O34: dmz-streaming | P34: Profile Group: threat-prevention-only | Q34: Traffic log sent at session end;Log Forwarding Profile setting: Forward to Panorama | R34: Partially Used | S34: INC1213850 | T34: 0 | U34: - | V34: 10/7/2025 11:23 | W34: 10/7/2025 11:23 | AA34: False,0 | AB34: False,0 | AC34: False,0 | AD34: False,0 | AE34: False,0 | AF34: False,0 | AG34: False,0 | AH34: False,0 | AI34: False,0 | AJ34: False,0 | AK34: False,0 | AL34: False,0 | AM34: False,0 | AN34: True,2 | AO34: False,0 | AP34: False,0 | AQ34: False,0 | AR34: False,0 | AS34: False,0 | AT34: 10 | AU34: False,0 | AV34: False,0 | AW34: 1 | AX34: False,0 | AY34: False,0 | BA34: False,0
A35: 10.0.0.0/8; 138.32.0.0/16; 153.15.0.0/16; 155.191.0.0/16; 158.139.0.0/16; 159.163.0.0/16; 172.16.0.0/12; 192.168.0.0/16 | B35: 172.26.36.245; 172.26.36.28; 172.26.36.29; 172.27.36.104; 172.27.36.105; 172.27.36.245 | C35: application-default | D35: 443,tcp | E35: Allow | F35: 10 | G35: Low | H35: otpcnfw-bvl-hoc Policies.csv | I35: 4.0 to 3.5 - Enterprise User Access to 3.5 Clarota SRA | J35: otpcnfw-bvl-hoc | K35: none | L35: universal | M35: dmz-copent | N35: any | O35: dmz-remote-access | P35: Profile Group: threat-prevention-only | Q35: Traffic log sent at session end;Log Forwarding Profile setting: Forward to Panorama | R35: Partially Used | S35: INC0250287 | T35: 1 | U35: 1 | V35: 3/19/2025 5:06 | W35: 4/23/2024 10:43 | AA35: False,0 | AB35: True,10 | AC35: False,0 | AD35: False,0 | AE35: False,0 | AF35: False,0 | AG35: False,0 | AH35: False,0 | AI35: False,0 | AJ35: False,0 | AK35: False,0 | AL35: False,0 | AM35: False,0 | AN35: True,2 | AO35: False,0 | AP35: False,0 | AQ35: False,0 | AR35: False,0 | AS35: False,0 | AT35: 0 | AU35: False,0 | AV35: False,0 | AW35: 1 | AX35: False,0 | AY35: False,0 | BA35: False,0
... A50: 172.26.17.163 | B50: [Negate] grp-ConocoPhillips | C50: application-default | D50: 25,587,tcp | E50: Allow | F50: 0 | G50: Low | H50: otpcnfw-bvl-hoc Policies.csv | I50: 3.5 to 4.0 - Worktask 2023 Send Receive from Exchange SMTP | J50: otpcnfw-bvl-hoc | K50: none | L50: universal | M50: dmz-cygnet | N50: any | O50: dmz-copent | P50: Profile Group: threat-prevention-only | Q50: Traffic log sent at session end;Log Forwarding Profile setting: Forward to Panorama | R50: Partially Used | S50: INC1163133;Randy has asked to test this without the Proxy, once connection is stable and confirmed working we will look to move forward with the proxy. | T50: 0 | U50: - | V50: 9/22/2025 11:01 | W50: 9/22/2025 10:54 | AA50: False,0 | AB50: False,0 | AC50: False,0 | AD50: False,0 | AE50: False,0 | AF50: False,0 | AG50: False,0 | AH50: False,0 | AI50: False,0 | AJ50: False,0 | AK50: False,0 | AL50: False,0 | AM50: False,0 | AN50: True,2 | AO50: False,0 | AP50: False,0 | AQ50: False,0 | AR50: False,0 | AS50: False,0 | AT50: 0 | AU50: False,0 | AV50: False,0 | AW50: 2 | AX50: False,0 | AY50: False,0 | BA50: False,0
A51: 172.26.17.163 | B51: [Negate] grp-ConocoPhillips | C51: TCP/110; TCP/587; TCP/995 | D51: any | E51: Allow | F51: 15 | G51: Low | H51: otpcnfw-bvl-hoc Policies.csv | I51: 3.5 to 4.0 - Worktask 2023 Send Receive from Exchange ports | J51: otpcnfw-bvl-hoc | K51: none | L51: universal | M51: dmz-cygnet | N51: any | O51: dmz-copent | P51: Profile Group: threat-prevention-only | Q51: Traffic log sent at session end;Log Forwarding Profile setting: Forward to Panorama | R51: Partially Used | S51: INC1163133;Randy has asked to test this without the Proxy, once connection is stable and confirmed working we will look to move forward with the proxy. | T51: 1 | U51: 32 | V51: 9/22/2025 10:54 | W51: 9/5/2025 10:34 | AA51: False,0 | AB51: False,0 | AC51: False,0 | AD51: False,0 | AE51: False,0 | AF51: False,0 | AG51: False,0 | AH51: False,0 | AI51: False,0 | AJ51: True,10 | AK51: True,5 | AL51: False,0 | AM51: False,0 | AN51: True,2 | AO51: False,0 | AP51: False,0 | AQ51: False,0 | AR51: False,0 | AS51: False,0 | AT51: 3 | AU51: False,0 | AV51: True,0 | AW51: 65535 | AX51: True,0 | AY51: False,0 | AZ51: pop3 | BA51: True,10
A52: 172.26.17.163 | B52: any | C52: application-default | D52: 443,80,tcp; 443,tcp; 80,tcp | E52: Allow | F52: 10 | G52: Low | H52: otpcnfw-bvl-hoc Policies.csv | I52: Internet Access URLs - Worktask 2023 Certificate Validation | J52: otpcnfw-bvl-hoc | K52: none | L52: universal | M52: dmz-cygnet | N52: any | O52: dmz-copent | P52: Profile Group: threat-prevention-only | Q52: Traffic log sent at session end;Log Forwarding Profile setting: Forward to Panorama | R52: Partially Used | S52: INC1183744 - Need to allow CRL to be reached for cert validation - tmonea | T52: 0 | U52: - | V52: 9/22/2025 15:59 | W52: 9/22/2025 15:13 | AA52: False,0 | AB52: False,0 | AC52: False,0 | AD52: True,10 | AE52: False,0 | AF52: False,0 | AG52: False,0 | AH52: False,0 | AI52: False,0 | AJ52: False,0 | AK52: False,0 | AL52: False,0 | AM52: False,0 | AN52: True,2 | AO52: False,0 | AP52: False,0 | AQ52: False,0 | AR52: False,0 | AS52: False,0 | AT52: 0 | AU52: False,0 | AV52: False,0 | AW52: 2 | AX52: False,0 | AY52: False,0 | BA52: False,0
A53: 172.26.32.66 | B53: 158.139.126.6; 158.139.126.7; 158.139.137.189; 158.139.166.163; 158.139.175.68 | C53: application-default | D53: 8000,8004,8089,9887,9989,9997,9998,tcp; 80,tcp | E53: Allow | F53: 0 | G53: Low | H53: otpcnfw-bvl-hoc Policies.csv | I53: 3.5 to 4.0 - DMZ Splunk to Enterprise Splunk | J53: otpcnfw-bvl-hoc | K53: none | L53: universal | M53: dmz-splunk | N53: any | O53: dmz-copent | P53: Profile Group: threat-prevention-only | Q53: Traffic log sent at session end;Log Forwarding Profile setting: Forward to Panorama | R53: Unused | S53: INC0051565 | T53: 0 | U53: - | V53: 3/19/2025 5:06 | W53: 2/10/2024 9:58 | AA53: False,0 | AB53: False,0 | AC53: False,0 | AD53: False,0 | AE53: False,0 | AF53: False,0 | AG53: False,0 | AH53: False,0 | AI53: False,0 | AJ53: False,0 | AK53: False,0 | AL53: False,0 | AM53: False,0 | AN53: True,5 | AO53: False,0 | AP53: False,0 | AQ53: False,0 | AR53: False,0 | AS53: False,0 | AT53: 0 | AU53: False,0 | AV53: False,0 | AW53: 8 | AX53: False,0 | AY53: False,0 | BA53: False,0
A54: 172.26.32.68; 172.26.32.67; 172.26.33.207; 172.27.32.94 | B54: 158.139.175.68 | C54: application-default | D54: 8000,8004,8089,9887,9989,9997,9998,tcp | E54: Allow | F54: 0 | G54: Low | H54: otpcnfw-bvl-hoc Policies.csv | I54: 3.5 to 4.0 - Splunk Heavy Forwarder to Licensing Server | J54: otpcnfw-bvl-hoc | K54: none | L54: universal | M54: dmz-automation;dmz-splunk | N54: any | O54: dmz-copent | P54: Profile Group: threat-prevention-only | Q54: Traffic log sent at session end;Log Forwarding Profile setting: Forward to Panorama | R54: Used | S54: INC0091373 INC0114725 INC0366158 | T54: 0 | U54: - | V54: 3/19/2025 5:06 | W54: 2/10/2024 9:58 | AA54: False,0 | AB54: False,0 | AC54: False,0 | AD54: False,0 | AE54: False,0 | AF54: False,0 | AG54: False,0 | AH54: False,0 | AI54: False,0 | AJ54: False,0 | AK54: False,0 | AL54: False,0 | AM54: False,0 | AN54: False,0 | AO54: False,0 | AP54: False,0 | AQ54: False,0 | AR54: False,0 | AS54: False,0 | AT54: 0 | AU54: False,0 | AV54: False,0 | AW54: 7 | AX54: False,0 | AY54: False,0 | BA54: False,0
...

Sheet Raw Data
A1: Source_File | B1: Name | C1: Location | D1: Tags | E1: Type | F1: Source Zone | G1: Source Address | H1: Source User | I1: Destination Zone | J1: Destination Address | K1: Application | L1: Service | M1: Action | N1: Profile | O1: Options | P1: Rule Usage Rule Usage | Q1: Rule Usage Description | R1: Rule Usage Apps Seen | S1: Days With No New Apps | T1: Modified | U1: Created | V1: Rule Usage First Hit | W1: Rule Usage Hit Count | X1: Rule Usage Last Hit | Y1: Src_IsAny | Z1: Src_CIDR_Le_16 | AA1: Src_CIDR_17_22 | AB1: Dst_IsAny | AC1: Dst_CIDR_Le_16 | AD1: Dst_CIDR_17_22 | AE1: SrcZone_IsAny | AF1: DstZone_IsAny | AG1: Service_Any_OR_RangeGt1000 | AH1: App_Any_OR_RangeGt1000 | AI1: Service_Insecure_Match | AJ1: Risky_Inbound | AK1: Risky_Outbound | AL1: Rule_Usage_Scoring | AM1: Rule_Usage_Description_Scoring | AN1: Source_User_Scoring | AO1: Profile_Scoring | AP1: Options_Scoring | AQ1: Service_IsAny | AR1: Service_UniquePorts_Total | AS1: Service_RangeGt1000 | AT1: App_IsAny | AU1: App_UniquePorts_Total | AV1: App_RangeGt1000 | AW1: Action_IsDenyOrDrop | AX1: Score_Total | AY1: Migrate Insecure | AZ1: Migrate_Insecure
A2: otpcnfw-bvl-hoc Policies.csv | B2: [Disabled] Internet Access - Jumpboxes to Internet | C2: otpcnfw-bvl-hoc | D2: [Disabled] none | E2: [Disabled] universal | F2: [Disabled] dmz-remote-access | G2: [Disabled] bvlotwjump3501.l48ics.net; [Disabled] bvlotwjump3502.l48ics.net; [Disabled] bvlotwjump3503.l48ics.net | H2: [Disabled] any | I2: [Disabled] dmz-copent | J2: [Negate] [Disabled] grp-ConocoPhillips | K2: [Disabled] ssl; [Disabled] web-browsing | L2: [Disabled] application-default | M2: [Disabled] Allow | N2: Profile Group: threat-prevention-only | O2: Traffic log sent at session end;Log Forwarding Profile setting: Forward to Panorama | P2: Partially Used | Q2: [Disabled] INC0015648 INC0022770 INC0041121 INC0044990 INC0046388 INC0046850 INC0062282 INC0081699 INC0059031 INC0060904 INC1145765;[Disabled] Disabled as Jumpboxes do not exist | R2: 18 | S2: 154 | T2: 9/3/2025 10:32 | U2: 2/10/2024 9:58 | Y2: {=IF(FALSE,"True," & IF(_xlfn.XLOOKUP("Src_IsAny",'Scoring_Config'!$A:$A,'Scoring_Config'!$D:$D,"Yes")="Yes",_xlfn.XLOOKUP("Src_IsAny",'Scoring_Config'!$A:$A,'Scoring_Config'!$C:$C,10),0),"False,0")} -> 0 | Z2: {=IF(FALSE,"True," & IF(_xlfn.XLOOKUP("Src_CIDR_Le_16",'Scoring_Config'!$A:$A,'Scoring_Config'!$D:$D,"Yes")="Yes",_xlfn.XLOOKUP("Src_CIDR_Le_16",'Scoring_Config'!$A:$A,'Scoring_Config'!$C:$C,10),0),"False,0")} -> 0 | AA2: {=IF(FALSE,"True," & IF(_xlfn.XLOOKUP("Src_CIDR_17_22",'Scoring_Config'!$A:$A,'Scoring_Config'!$D:$D,"Yes")="Yes",_xlfn.XLOOKUP("Src_CIDR_17_22",'Scoring_Config'!$A:$A,'Scoring_Config'!$C:$C,5),0),"False,0")} -> 0 | AB2: {=IF(FALSE,"True," & IF(_xlfn.XLOOKUP("Dst_IsAny",'Scoring_Config'!$A:$A,'Scoring_Config'!$D:$D,"Yes")="Yes",_xlfn.XLOOKUP("Dst_IsAny",'Scoring_Config'!$A:$A,'Scoring_Config'!$C:$C,10),0),"False,0")} -> 0 | AC2: {=IF(FALSE,"True," & IF(_xlfn.XLOOKUP("Dst_CIDR_Le_16",'Scoring_Config'!$A:$A,'Scoring_Config'!$D:$D,"Yes")="Yes",_xlfn.XLOOKUP("Dst_CIDR_Le_16",'Scoring_Config'!$A:$A,'Scoring_Config'!$C:$C,10),0),"False,0")} -> 0 | AD2: {=IF(FALSE,"True," & IF(_xlfn.XLOOKUP("Dst_CIDR_17_22",'Scoring_Config'!$A:$A,'Scoring_Config'!$D:$D,"Yes")="Yes",_xlfn.XLOOKUP("Dst_CIDR_17_22",'Scoring_Config'!$A:$A,'Scoring_Config'!$C:$C,5),0),"False,0")} -> 0 | AE2: {=IF(FALSE,"True," & IF(_xlfn.XLOOKUP("SrcZone_IsAny",'Scoring_Config'!$A:$A,'Scoring_Config'!$D:$D,"Yes")="Yes",_xlfn.XLOOKUP("SrcZone_IsAny",'Scoring_Config'!$A:$A,'Scoring_Config'!$C:$C,10),0),"False,0")} -> 0 | AF2: {=IF(FALSE,"True," & IF(_xlfn.XLOOKUP("DstZone_IsAny",'Scoring_Config'!$A:$A,'Scoring_Config'!$D:$D,"Yes")="Yes",_xlfn.XLOOKUP("DstZone_IsAny",'Scoring_Config'!$A:$A,'Scoring_Config'!$C:$C,10),0),"False,0")} -> 0 | AG2: {=IF(FALSE,"True," & IF(_xlfn.XLOOKUP("Service_Any_OR_RangeGt1000",'Scoring_Config'!$A:$A,'Scoring_Config'!$D:$D,"Yes")="Yes",_xlfn.XLOOKUP("Service_Any_OR_RangeGt1000",'Scoring_Config'!$A:$A,'Scoring_Config'!$C:$C,10),0),"False,0")} -> 0 | AH2: {=IF(FALSE,"True," & IF(_xlfn.XLOOKUP("App_Any_OR_RangeGt1000",'Scoring_Config'!$A:$A,'Scoring_Config'!$D:$D,"Yes")="Yes",_xlfn.XLOOKUP("App_Any_OR_RangeGt1000",'Scoring_Config'!$A:$A,'Scoring_Config'!$C:$C,10),0),"False,0")} -> 0 | AI2: {=IF(FALSE,"True," & IF(_xlfn.XLOOKUP("Service_Insecure_Match",'Scoring_Config'!$A:$A,'Scoring_Config'!$D:$D,"Yes")="Yes",_xlfn.XLOOKUP("Service_Insecure_Match",'Scoring_Config'!$A:$A,'Scoring_Config'!$C:$C,5),0),"False,0")} -> 0 | AJ2: {=IF(FALSE,"True," & IF(_xlfn.XLOOKUP("Risky_Inbound",'Scoring_Config'!$A:$A,'Scoring_Config'!$D:$D,"Yes")="Yes",_xlfn.XLOOKUP("Risky_Inbound",'Scoring_Config'!$A:$A,'Scoring_Config'!$C:$C,50),0),"False,0")} -> 0 | AK2: {=IF(FALSE,"True," & IF(_xlfn.XLOOKUP("Risky_Outbound",'Scoring_Config'!$A:$A,'Scoring_Config'!$D:$D,"Yes")="Yes",_xlfn.XLOOKUP("Risky_Outbound",'Scoring_Config'!$A:$A,'Scoring_Config'!$C:$C,25),0),"False,0")} -> 0 | AL2: True,2 | AM2: {=IF(FALSE,"True," & IF(_xlfn.XLOOKUP("Rule_Usage_Description_Scoring",'Scoring_Config'!$A:$A,'Scoring_Config'!$D:$D,"Yes")="Yes",_xlfn.XLOOKUP("Rule_Usage_Description_Scoring",'Scoring_Config'!$A:$A,'Scoring_Config'!$C:$C,4),0),"False,0")} -> 0 | AN2: False,0 | AO2: False,0 | AP2: False,0 | AQ2: {=IF(FALSE,"True," & IF(_xlfn.XLOOKUP("Service_IsAny",'Scoring_Config'!$A:$A,'Scoring_Config'!$D:$D,"Yes")="Yes",_xlfn.XLOOKUP("Service_IsAny",'Scoring_Config'!$A:$A,'Scoring_Config'!$C:$C,0),0),"False,0")} -> 0 | AR2: 0 | AS2: {=IF(FALSE,"True," & IF(_xlfn.XLOOKUP("Service_RangeGt1000",'Scoring_Config'!$A:$A,'Scoring_Config'!$D:$D,"Yes")="Yes",_xlfn.XLOOKUP("Service_RangeGt1000",'Scoring_Config'!$A:$A,'Scoring_Config'!$C:$C,0),0),"False,0")} -> 0 | AT2: {=IF(FALSE,"True," & IF(_xlfn.XLOOKUP("App_IsAny",'Scoring_Config'!$A:$A,'Scoring_Config'!$D:$D,"Yes")="Yes",_xlfn.XLOOKUP("App_IsAny",'Scoring_Config'!$A:$A,'Scoring_Config'!$C:$C,0),0),"False,0")} -> 0 | AU2: 0 | AV2: {=IF(FALSE,"True," & IF(_xlfn.XLOOKUP("App_RangeGt1000",'Scoring_Config'!$A:$A,'Scoring_Config'!$D:$D,"Yes")="Yes",_xlfn.XLOOKUP("App_RangeGt1000",'Scoring_Config'!$A:$A,'Scoring_Config'!$C:$C,0),0),"False,0")} -> 0 | AW2: {=IF(FALSE,"True," & IF(_xlfn.XLOOKUP("Action_IsDenyOrDrop",'Scoring_Config'!$A:$A,'Scoring_Config'!$D:$D,"Yes")="Yes",_xlfn.XLOOKUP("Action_IsDenyOrDrop",'Scoring_Config'!$A:$A,'Scoring_Config'!$C:$C,0),0),"False,0")} -> 0 | AX2: {=IF(LEFT(AW2,4)="True",0,(IF(LEFT(Y2,4)="True",IF(_xlfn.XLOOKUP("Src_IsAny",'Scoring_Config'!$A:$A,'Scoring_Config'!$D:$D,"Yes")="Yes",_xlfn.XLOOKUP("Src_IsAny",'Scoring_Config'!$A:$A,'Scoring_Config'!$C:$C,10),0),0)+IF(LEFT(Z2,4)="True",IF(_xlfn.XLOOKUP("Src_CIDR_Le_16",'Scoring_Config'!$A:$A,'Scoring_Config'!$D:$D,"Yes")="Yes",_xlfn.XLOOKUP("Src_CIDR_Le_16",'Scoring_Config'!$A:$A,'Scoring_Config'!$C:$C,10),0),0)+IF(LEFT(AA2,4)="True",IF(_xlfn.XLOOKUP("Src_CIDR_17_22",'Scoring_Config'!$A:$A,'Scoring_Config'!$D:$D,"Yes")="Yes",_xlfn.XLOOKUP("Src_CIDR_17_22",'Scoring_Config'!$A:$A,'Scoring_Config'!$C:$C,5),0),0)+IF(LEFT(AB2,4)="True",IF(_xlfn.XLOOKUP("Dst_IsAny",'Scoring_Config'!$A:$A,'Scoring_Config'!$D:$D,"Yes")="Yes",_xlfn.XLOOKUP("Dst_IsAny",'Scoring_Config'!$A:$A,'Scoring_Config'!$C:$C,10),0),0)+IF(LEFT(AC2,4)="True",IF(_xlfn.XLOOKUP("Dst_CIDR_Le_16",'Scoring_Config'!$A:$A,'Scoring_Config'!$D:$D,"Yes")="Yes",_xlfn.XLOOKUP("Dst_CIDR_Le_16",'Scoring_Config'!$A:$A,'Scoring_Config'!$C:$C,10),0),0)+IF(LEFT(AD2,4)="True",IF(_xlfn.XLOOKUP("Dst_CIDR_17_22",'Scoring_Config'!$A:$A,'Scoring_Config'!$D:$D,"Yes")="Yes",_xlfn.XLOOKUP("Dst_CIDR_17_22",'Scoring_Config'!$A:$A,'Scoring_Config'!$C:$C,5),0),0)+IF(LEFT(AE2,4)="True",IF(_xlfn.XLOOKUP("SrcZone_IsAny",'Scoring_Config'!$A:$A,'Scoring_Config'!$D:$D,"Yes")="Yes",_xlfn.XLOOKUP("SrcZone_IsAny",'Scoring_Config'!$A:$A,'Scoring_Config'!$C:$C,10),0),0)+IF(LEFT(AF2,4)="True",IF(_xlfn.XLOOKUP("DstZone_IsAny",'Scoring_Config'!$A:$A,'Scoring_Config'!$D:$D,"Yes")="Yes",_xlfn.XLOOKUP("DstZone_IsAny",'Scoring_Config'!$A:$A,'Scoring_Config'!$C:$C,10),0),0)+IF(LEFT(AG2,4)="True",IF(_xlfn.XLOOKUP("Service_Any_OR_RangeGt1000",'Scoring_Config'!$A:$A,'Scoring_Config'!$D:$D,"Yes")="Yes",_xlfn.XLOOKUP("Service_Any_OR_RangeGt1000",'Scoring_Config'!$A:$A,'Scoring_Config'!$C:$C,10),0),0)+IF(LEFT(AH2,4)="True",IF(_xlfn.XLOOKUP("App_Any_OR_RangeGt1000",'Scoring_Config'!$A:$A,'Scoring_Config'!$D:$D,"Yes")="Yes",_xlfn.XLOOKUP("App_Any_OR_RangeGt1000",'Scoring_Config'!$A:$A,'Scoring_Config'!$C:$C,10),0),0)+IF(LEFT(AI2,4)="True",IF(_xlfn.XLOOKUP("Service_Insecure_Match",'Scoring_Config'!$A:$A,'Scoring_Config'!$D:$D,"Yes")="Yes",_xlfn.XLOOKUP("Service_Insecure_Match",'Scoring_Config'!$A:$A,'Scoring_Config'!$C:$C,5),0),0)+IF(LEFT(AJ2,4)="True",IF(_xlfn.XLOOKUP("Risky_Inbound",'Scoring_Config'!$A:$A,'Scoring_Config'!$D:$D,"Yes")="Yes",_xlfn.XLOOKUP("Risky_Inbound",'Scoring_Config'!$A:$A,'Scoring_Config'!$C:$C,50),0),0)+IF(LEFT(AK2,4)="True",IF(_xlfn.XLOOKUP("Risky_Outbound",'Scoring_Config'!$A:$A,'Scoring_Config'!$D:$D,"Yes")="Yes",_xlfn.XLOOKUP("Risky_Outbound",'Scoring_Config'!$A:$A,'Scoring_Config'!$C:$C,25),0),0)+IF(LEFT(AZ2,4)="True",IF(_xlfn.XLOOKUP("Migrate_Insecure",'Scoring_Config'!$A:$A,'Scoring_Config'!$D:$D,"Yes")="Yes",_xlfn.XLOOKUP("Migrate_Insecure",'Scoring_Config'!$A:$A,'Scoring_Config'!$C:$C,10),0),0)+IF(_xlfn.XLOOKUP("Rule_Usage_Scoring",'Scoring_Config'!$A:$A,'Scoring_Config'!$D:$D,"Yes")="Yes",VALUE(MID(AL2,FIND(",",AL2)+1,100)),0)+IF(LEFT(AM2,4)="True",IF(_xlfn.XLOOKUP("Rule_Usage_Description_Scoring",'Scoring_Config'!$A:$A,'Scoring_Config'!$D:$D,"Yes")="Yes",_xlfn.XLOOKUP("Rule_Usage_Description_Scoring",'Scoring_Config'!$A:$A,'Scoring_Config'!$C:$C,4),0),0)+IF(_xlfn.XLOOKUP("Source_User_Scoring",'Scoring_Config'!$A:$A,'Scoring_Config'!$D:$D,"Yes")="Yes",VALUE(MID(AN2,FIND(",",AN2)+1,100)),0)+IF(_xlfn.XLOOKUP("Profile_Scoring",'Scoring_Config'!$A:$A,'Scoring_Config'!$D:$D,"Yes")="Yes",VALUE(MID(AO2,FIND(",",AO2)+1,100)),0)+IF(_xlfn.XLOOKUP("Options_Scoring",'Scoring_Config'!$A:$A,'Scoring_Config'!$D:$D,"Yes")="Yes",VALUE(MID(AP2,FIND(",",AP2)+1,100)),0)))} -> 0 | AZ2: {=IF(FALSE,"True," & IF(_xlfn.XLOOKUP("Migrate_Insecure",'Scoring_Config'!$A:$A,'Scoring_Config'!$D:$D,"Yes")="Yes",_xlfn.XLOOKUP("Migrate_Insecure",'Scoring_Config'!$A:$A,'Scoring_Config'!$C:$C,10),0),"False,0")} -> 0
