Workbook

Sheet Raw Data
A1: Source_File | B1: Name | C1: Location | D1: Tags | E1: Type | F1: Source Zone | G1: Source Address_original | H1: Source Address | I1: Source User | J1: Destination Zone | K1: Destination Address_original | L1: Destination Address | M1: Application_original | N1: Application | O1: Service_original | P1: Service | Q1: Action | R1: Profile | S1: Options | T1: Rule Usage Rule Usage | U1: Rule Usage Description | V1: Rule Usage Apps Seen | W1: Days With No New Apps | X1: Modified | Y1: Created | Z1: Rule Usage First Hit | AA1: Rule Usage Hit Count | AB1: Rule Usage Last Hit | AC1: Src_IsAny | AD1: Src_CIDR_Le_16 | AE1: Src_CIDR_17_22 | AF1: Dst_IsAny | AG1: Dst_CIDR_Le_16 | AH1: Dst_CIDR_17_22 | AI1: SrcZone_IsAny | AJ1: DstZone_IsAny | AK1: Service_Any_OR_RangeGt1000 | AL1: App_Any_OR_RangeGt1000 | AM1: Service_Insecure_Match | AN1: Risky_Inbound | AO1: Risky_Outbound | AP1: Rule_Usage_Scoring | AQ1: Rule_Usage_Description_Scoring | AR1: Source_User_Scoring | AS1: Profile_Scoring | AT1: Options_Scoring | AU1: Action_IsDenyOrDrop | AV1: Migrate Insecure_AppID | AW1: Migrate_Insecure | AX1: Migrate_Other_ports | AY1: Migrate_Other_ports_Score | AZ1: Score_Total
A2: DC_Policies_Export.csv | B2: Block_DMZ_to_Mgmt_VNC | C2: la-datacenterfw | E2: universal | F2: DMZ | G2: net-tier-10_1_3_0_24 | H2: 10.1.3.0/24 | I2: any | J2: Mgmt | K2: 10.1.1.0/24 | L2: 10.1.1.0/24 | M2: LA_App_Any_And_Web | N2: 443,tcp; 80,tcp; any | O2: vnc-tcp-5900 | P2: TCP/5900 | Q2: deny | R2: threat-prevention | S2: log at both ends | T2: 9019 | U2: Exception tracked in INC849758 pending remediation | V2: unknown-tcp | W2: 156 | X2: 2025-06-28 01:07:58 | Y2: 2022-07-05 01:07:58 | AC2: {=IF(FALSE,"True," & IF(_xlfn.XLOOKUP("Src_IsAny",'Scoring_Config'!$A:$A,'Scoring_Config'!$D:$D,"Yes")="Yes",_xlfn.XLOOKUP("Src_IsAny",'Scoring_Config'!$A:$A,'Scoring_Config'!$C:$C,25),0),"False,0")} -> 0 | AD2: {=IF(FALSE,"True," & IF(_xlfn.XLOOKUP("Src_CIDR_Le_16",'Scoring_Config'!$A:$A,'Scoring_Config'!$D:$D,"Yes")="Yes",_xlfn.XLOOKUP("Src_CIDR_Le_16",'Scoring_Config'!$A:$A,'Scoring_Config'!$C:$C,25),0),"False,0")} -> 0 | AE2: {=IF(FALSE,"True," & IF(_xlfn.XLOOKUP("Src_CIDR_17_22",'Scoring_Config'!$A:$A,'Scoring_Config'!$D:$D,"Yes")="Yes",_xlfn.XLOOKUP("Src_CIDR_17_22",'Scoring_Config'!$A:$A,'Scoring_Config'!$C:$C,15),0),"False,0")} -> 0 | AF2: {=IF(FALSE,"True," & IF(_xlfn.XLOOKUP("Dst_IsAny",'Scoring_Config'!$A:$A,'Scoring_Config'!$D:$D,"Yes")="Yes",_xlfn.XLOOKUP("Dst_IsAny",'Scoring_Config'!$A:$A,'Scoring_Config'!$C:$C,25),0),"False,0")} -> 0 | AG2: {=IF(FALSE,"True," & IF(_xlfn.XLOOKUP("Dst_CIDR_Le_16",'Scoring_Config'!$A:$A,'Scoring_Config'!$D:$D,"Yes")="Yes",_xlfn.XLOOKUP("Dst_CIDR_Le_16",'Scoring_Config'!$A:$A,'Scoring_Config'!$C:$C,25),0),"False,0")} -> 0 | AH2: {=IF(FALSE,"True," & IF(_xlfn.XLOOKUP("Dst_CIDR_17_22",'Scoring_Config'!$A:$A,'Scoring_Config'!$D:$D,"Yes")="Yes",_xlfn.XLOOKUP("Dst_CIDR_17_22",'Scoring_Config'!$A:$A,'Scoring_Config'!$C:$C,15),0),"False,0")} -> 0 | AI2: {=IF(FALSE,"True," & IF(_xlfn.XLOOKUP("SrcZone_IsAny",'Scoring_Config'!$A:$A,'Scoring_Config'!$D:$D,"Yes")="Yes",_xlfn.XLOOKUP("SrcZone_IsAny",'Scoring_Config'!$A:$A,'Scoring_Config'!$C:$C,5),0),"False,0")} -> 0 | AJ2: {=IF(FALSE,"True," & IF(_xlfn.XLOOKUP("DstZone_IsAny",'Scoring_Config'!$A:$A,'Scoring_Config'!$D:$D,"Yes")="Yes",_xlfn.XLOOKUP("DstZone_IsAny",'Scoring_Config'!$A:$A,'Scoring_Config'!$C:$C,5),0),"False,0")} -> 0 | AK2: {=IF(FALSE,"True," & IF(_xlfn.XLOOKUP("Service_Any_OR_RangeGt1000",'Scoring_Config'!$A:$A,'Scoring_Config'!$D:$D,"Yes")="Yes",_xlfn.XLOOKUP("Service_Any_OR_RangeGt1000",'Scoring_Config'!$A:$A,'Scoring_Config'!$C:$C,25),0),"False,0")} -> 0 | AL2: {=IF(TRUE,"True," & IF(_xlfn.XLOOKUP("App_Any_OR_RangeGt1000",'Scoring_Config'!$A:$A,'Scoring_Config'!$D:$D,"Yes")="Yes",_xlfn.XLOOKUP("App_Any_OR_RangeGt1000",'Scoring_Config'!$A:$A,'Scoring_Config'!$C:$C,25),0),"False,0")} -> 0 | AM2: {=IF(TRUE,"True," & IF(_xlfn.XLOOKUP("Service_Insecure_Match",'Scoring_Config'!$A:$A,'Scoring_Config'!$D:$D,"Yes")="Yes",_xlfn.XLOOKUP("Service_Insecure_Match",'Scoring_Config'!$A:$A,'Scoring_Config'!$C:$C,20),0),"False,0")} -> 0 | AN2: {=IF(FALSE,"True," & IF(_xlfn.XLOOKUP("Risky_Inbound",'Scoring_Config'!$A:$A,'Scoring_Config'!$D:$D,"Yes")="Yes",_xlfn.XLOOKUP("Risky_Inbound",'Scoring_Config'!$A:$A,'Scoring_Config'!$C:$C,20),0),"False,0")} -> 0 | AO2: {=IF(FALSE,"True," & IF(_xlfn.XLOOKUP("Risky_Outbound",'Scoring_Config'!$A:$A,'Scoring_Config'!$D:$D,"Yes")="Yes",_xlfn.XLOOKUP("Risky_Outbound",'Scoring_Config'!$A:$A,'Scoring_Config'!$C:$C,10),0),"False,0")} -> 0 | AP2: True,5 | AQ2: {=IF(FALSE,"True," & IF(_xlfn.XLOOKUP("Rule_Usage_Description_Scoring",'Scoring_Config'!$A:$A,'Scoring_Config'!$D:$D,"Yes")="Yes",_xlfn.XLOOKUP("Rule_Usage_Description_Scoring",'Scoring_Config'!$A:$A,'Scoring_Config'!$C:$C,5),0),"False,0")} -> 0 | AR2: False,0 | AS2: False,0 | AT2: False,0 | AU2: {=IF(TRUE,"True," & IF(_xlfn.XLOOKUP("Action_IsDenyOrDrop",'Scoring_Config'!$A:$A,'Scoring_Config'!$D:$D,"Yes")="Yes",_xlfn.XLOOKUP("Action_IsDenyOrDrop",'Scoring_Config'!$A:$A,'Scoring_Config'!$C:$C,0),0),"False,0")} -> 0 | AW2: {=IF(FALSE,"True," & IF(_xlfn.XLOOKUP("Migrate_Insecure",'Scoring_Config'!$A:$A,'Scoring_Config'!$D:$D,"Yes")="Yes",_xlfn.XLOOKUP("Migrate_Insecure",'Scoring_Config'!$A:$A,'Scoring_Config'!$C:$C,15),0),"False,0")} -> 0 | AY2: {=IF(FALSE,"True," & IF(_xlfn.XLOOKUP("Migrate_Other_Ports",'Scoring_Config'!$A:$A,'Scoring_Config'!$D:$D,"Yes")="Yes",_xlfn.XLOOKUP("Migrate_Other_Ports",'Scoring_Config'!$A:$A,'Scoring_Config'!$C:$C,5),0),"False,0")} -> 0 | AZ2: {=IF(LEFT(AU2,4)="True",0,(IF(LEFT(AC2,4)="True",IF(_xlfn.XLOOKUP("Src_IsAny",'Scoring_Config'!$A:$A,'Scoring_Config'!$D:$D,"Yes")="Yes",_xlfn.XLOOKUP("Src_IsAny",'Scoring_Config'!$A:$A,'Scoring_Config'!$C:$C,25),0),0)+IF(LEFT(AD2,4)="True",IF(_xlfn.XLOOKUP("Src_CIDR_Le_16",'Scoring_Config'!$A:$A,'Scoring_Config'!$D:$D,"Yes")="Yes",_xlfn.XLOOKUP("Src_CIDR_Le_16",'Scoring_Config'!$A:$A,'Scoring_Config'!$C:$C,25),0),0)+IF(LEFT(AE2,4)="True",IF(_xlfn.XLOOKUP("Src_CIDR_17_22",'Scoring_Config'!$A:$A,'Scoring_Config'!$D:$D,"Yes")="Yes",_xlfn.XLOOKUP("Src_CIDR_17_22",'Scoring_Config'!$A:$A,'Scoring_Config'!$C:$C,15),0),0)+IF(LEFT(AF2,4)="True",IF(_xlfn.XLOOKUP("Dst_IsAny",'Scoring_Config'!$A:$A,'Scoring_Config'!$D:$D,"Yes")="Yes",_xlfn.XLOOKUP("Dst_IsAny",'Scoring_Config'!$A:$A,'Scoring_Config'!$C:$C,25),0),0)+IF(LEFT(AG2,4)="True",IF(_xlfn.XLOOKUP("Dst_CIDR_Le_16",'Scoring_Config'!$A:$A,'Scoring_Config'!$D:$D,"Yes")="Yes",_xlfn.XLOOKUP("Dst_CIDR_Le_16",'Scoring_Config'!$A:$A,'Scoring_Config'!$C:$C,25),0),0)+IF(LEFT(AH2,4)="True",IF(_xlfn.XLOOKUP("Dst_CIDR_17_22",'Scoring_Config'!$A:$A,'Scoring_Config'!$D:$D,"Yes")="Yes",_xlfn.XLOOKUP("Dst_CIDR_17_22",'Scoring_Config'!$A:$A,'Scoring_Config'!$C:$C,15),0),0)+IF(LEFT(AI2,4)="True",IF(_xlfn.XLOOKUP("SrcZone_IsAny",'Scoring_Config'!$A:$A,'Scoring_Config'!$D:$D,"Yes")="Yes",_xlfn.XLOOKUP("SrcZone_IsAny",'Scoring_Config'!$A:$A,'Scoring_Config'!$C:$C,5),0),0)+IF(LEFT(AJ2,4)="True",IF(_xlfn.XLOOKUP("DstZone_IsAny",'Scoring_Config'!$A:$A,'Scoring_Config'!$D:$D,"Yes")="Yes",_xlfn.XLOOKUP("DstZone_IsAny",'Scoring_Config'!$A:$A,'Scoring_Config'!$C:$C,5),0),0)+IF(LEFT(AK2,4)="True",IF(_xlfn.XLOOKUP("Service_Any_OR_RangeGt1000",'Scoring_Config'!$A:$A,'Scoring_Config'!$D:$D,"Yes")="Yes",_xlfn.XLOOKUP("Service_Any_OR_RangeGt1000",'Scoring_Config'!$A:$A,'Scoring_Config'!$C:$C,25),0),0)+IF(LEFT(AL2,4)="True",IF(_xlfn.XLOOKUP("App_Any_OR_RangeGt1000",'Scoring_Config'!$A:$A,'Scoring_Config'!$D:$D,"Yes")="Yes",_xlfn.XLOOKUP("App_Any_OR_RangeGt1000",'Scoring_Config'!$A:$A,'Scoring_Config'!$C:$C,25),0),0)+IF(LEFT(AM2,4)="True",IF(_xlfn.XLOOKUP("Service_Insecure_Match",'Scoring_Config'!$A:$A,'Scoring_Config'!$D:$D,"Yes")="Yes",_xlfn.XLOOKUP("Service_Insecure_Match",'Scoring_Config'!$A:$A,'Scoring_Config'!$C:$C,20),0),0)+IF(LEFT(AN2,4)="True",IF(_xlfn.XLOOKUP("Risky_Inbound",'Scoring_Config'!$A:$A,'Scoring_Config'!$D:$D,"Yes")="Yes",_xlfn.XLOOKUP("Risky_Inbound",'Scoring_Config'!$A:$A,'Scoring_Config'!$C:$C,20),0),0)+IF(LEFT(AO2,4)="True",IF(_xlfn.XLOOKUP("Risky_Outbound",'Scoring_Config'!$A:$A,'Scoring_Config'!$D:$D,"Yes")="Yes",_xlfn.XLOOKUP("Risky_Outbound",'Scoring_Config'!$A:$A,'Scoring_Config'!$C:$C,10),0),0)+IF(LEFT(AW2,4)="True",IF(_xlfn.XLOOKUP("Migrate_Insecure",'Scoring_Config'!$A:$A,'Scoring_Config'!$D:$D,"Yes")="Yes",_xlfn.XLOOKUP("Migrate_Insecure",'Scoring_Config'!$A:$A,'Scoring_Config'!$C:$C,15),0),0)+IF(LEFT(AY2,4)="True",IF(_xlfn.XLOOKUP("Migrate_Other_Ports",'Scoring_Config'!$A:$A,'Scoring_Config'!$D:$D,"Yes")="Yes",_xlfn.XLOOKUP("Migrate_Other_Ports",'Scoring_Config'!$A:$A,'Scoring_Config'!$C:$C,5),0),0)+IF(_xlfn.XLOOKUP("Rule_Usage_Scoring",'Scoring_Config'!$A:$A,'Scoring_Config'!$D:$D,"Yes")="Yes",VALUE(MID(AP2,FIND(",",AP2)+1,100)),0)+IF(LEFT(AQ2,4)="True",IF(_xlfn.XLOOKUP("Rule_Usage_Description_Scoring",'Scoring_Config'!$A:$A,'Scoring_Config'!$D:$D,"Yes")="Yes",_xlfn.XLOOKUP("Rule_Usage_Description_Scoring",'Scoring_Config'!$A:$A,'Scoring_Config'!$C:$C,5),0),0)+IF(_xlfn.XLOOKUP("Source_User_Scoring",'Scoring_Config'!$A:$A,'Scoring_Config'!$D:$D,"Yes")="Yes",VALUE(MID(AR2,FIND(",",AR2)+1,100)),0)+IF(_xlfn.XLOOKUP("Profile_Scoring",'Scoring_Config'!$A:$A,'Scoring_Config'!$D:$D,"Yes")="Yes",VALUE(MID(AS2,FIND(",",AS2)+1,100)),0)+IF(_xlfn.XLOOKUP("Options_Scoring",'Scoring_Config'!$A:$A,'Scoring_Config'!$D:$D,"Yes")="Yes",VALUE(MID(AT2,FIND(",",AT2)+1,100)),0)))} -> 0
A3: DC_Policies_Export.csv | B3: Allow_Guest_to_DMZ_SMTP | C3: la-datacenterfw | E3: universal | F3: Untrust | G3: any | H3: any | I3: domain\itops | J3: Trust | K3: any | L3: any | M3: any | N3: any | O3: telnet-tcp-23 | P3: TCP/23 | Q3: allow | R3: none | S3: Traffic log sent at session end | T3: 1553 | V3: dns | W3: 188 | X3: 2025-03-29 21:09:58 | Y3: 2022-05-26 21:09:58 | AC3: {=IF(TRUE,"True," & IF(_xlfn.XLOOKUP("Src_IsAny",'Scoring_Config'!$A:$A,'Scoring_Config'!$D:$D,"Yes")="Yes",_xlfn.XLOOKUP("Src_IsAny",'Scoring_Config'!$A:$A,'Scoring_Config'!$C:$C,25),0),"False,0")} -> 0 | AD3: {=IF(FALSE,"True," & IF(_xlfn.XLOOKUP("Src_CIDR_Le_16",'Scoring_Config'!$A:$A,'Scoring_Config'!$D:$D,"Yes")="Yes",_xlfn.XLOOKUP("Src_CIDR_Le_16",'Scoring_Config'!$A:$A,'Scoring_Config'!$C:$C,25),0),"False,0")} -> 0 | AE3: {=IF(FALSE,"True," & IF(_xlfn.XLOOKUP("Src_CIDR_17_22",'Scoring_Config'!$A:$A,'Scoring_Config'!$D:$D,"Yes")="Yes",_xlfn.XLOOKUP("Src_CIDR_17_22",'Scoring_Config'!$A:$A,'Scoring_Config'!$C:$C,15),0),"False,0")} -> 0 | AF3: {=IF(TRUE,"True," & IF(_xlfn.XLOOKUP("Dst_IsAny",'Scoring_Config'!$A:$A,'Scoring_Config'!$D:$D,"Yes")="Yes",_xlfn.XLOOKUP("Dst_IsAny",'Scoring_Config'!$A:$A,'Scoring_Config'!$C:$C,25),0),"False,0")} -> 0 | AG3: {=IF(FALSE,"True," & IF(_xlfn.XLOOKUP("Dst_CIDR_Le_16",'Scoring_Config'!$A:$A,'Scoring_Config'!$D:$D,"Yes")="Yes",_xlfn.XLOOKUP("Dst_CIDR_Le_16",'Scoring_Config'!$A:$A,'Scoring_Config'!$C:$C,25),0),"False,0")} -> 0 | AH3: {=IF(FALSE,"True," & IF(_xlfn.XLOOKUP("Dst_CIDR_17_22",'Scoring_Config'!$A:$A,'Scoring_Config'!$D:$D,"Yes")="Yes",_xlfn.XLOOKUP("Dst_CIDR_17_22",'Scoring_Config'!$A:$A,'Scoring_Config'!$C:$C,15),0),"False,0")} -> 0 | AI3: {=IF(FALSE,"True," & IF(_xlfn.XLOOKUP("SrcZone_IsAny",'Scoring_Config'!$A:$A,'Scoring_Config'!$D:$D,"Yes")="Yes",_xlfn.XLOOKUP("SrcZone_IsAny",'Scoring_Config'!$A:$A,'Scoring_Config'!$C:$C,5),0),"False,0")} -> 0 | AJ3: {=IF(FALSE,"True," & IF(_xlfn.XLOOKUP("DstZone_IsAny",'Scoring_Config'!$A:$A,'Scoring_Config'!$D:$D,"Yes")="Yes",_xlfn.XLOOKUP("DstZone_IsAny",'Scoring_Config'!$A:$A,'Scoring_Config'!$C:$C,5),0),"False,0")} -> 0 | AK3: {=IF(FALSE,"True," & IF(_xlfn.XLOOKUP("Service_Any_OR_RangeGt1000",'Scoring_Config'!$A:$A,'Scoring_Config'!$D:$D,"Yes")="Yes",_xlfn.XLOOKUP("Service_Any_OR_RangeGt1000",'Scoring_Config'!$A:$A,'Scoring_Config'!$C:$C,25),0),"False,0")} -> 0 | AL3: {=IF(TRUE,"True," & IF(_xlfn.XLOOKUP("App_Any_OR_RangeGt1000",'Scoring_Config'!$A:$A,'Scoring_Config'!$D:$D,"Yes")="Yes",_xlfn.XLOOKUP("App_Any_OR_RangeGt1000",'Scoring_Config'!$A:$A,'Scoring_Config'!$C:$C,25),0),"False,0")} -> 0 | AM3: {=IF(TRUE,"True," & IF(_xlfn.XLOOKUP("Service_Insecure_Match",'Scoring_Config'!$A:$A,'Scoring_Config'!$D:$D,"Yes")="Yes",_xlfn.XLOOKUP("Service_Insecure_Match",'Scoring_Config'!$A:$A,'Scoring_Config'!$C:$C,20),0),"False,0")} -> 0 | AN3: {=IF(FALSE,"True," & IF(_xlfn.XLOOKUP("Risky_Inbound",'Scoring_Config'!$A:$A,'Scoring_Config'!$D:$D,"Yes")="Yes",_xlfn.XLOOKUP("Risky_Inbound",'Scoring_Config'!$A:$A,'Scoring_Config'!$C:$C,20),0),"False,0")} -> 0 | AO3: {=IF(FALSE,"True," & IF(_xlfn.XLOOKUP("Risky_Outbound",'Scoring_Config'!$A:$A,'Scoring_Config'!$D:$D,"Yes")="Yes",_xlfn.XLOOKUP("Risky_Outbound",'Scoring_Config'!$A:$A,'Scoring_Config'!$C:$C,10),0),"False,0")} -> 0 | AP3: True,5 | AQ3: {=IF(TRUE,"True," & IF(_xlfn.XLOOKUP("Rule_Usage_Description_Scoring",'Scoring_Config'!$A:$A,'Scoring_Config'!$D:$D,"Yes")="Yes",_xlfn.XLOOKUP("Rule_Usage_Description_Scoring",'Scoring_Config'!$A:$A,'Scoring_Config'!$C:$C,5),0),"False,0")} -> 0 | AR3: True,-10 | AS3: True,5 | AT3: False,0 | AU3: {=IF(FALSE,"True," & IF(_xlfn.XLOOKUP("Action_IsDenyOrDrop",'Scoring_Config'!$A:$A,'Scoring_Config'!$D:$D,"Yes")="Yes",_xlfn.XLOOKUP("Action_IsDenyOrDrop",'Scoring_Config'!$A:$A,'Scoring_Config'!$C:$C,0),0),"False,0")} -> 0 | AW3: {=IF(FALSE,"True," & IF(_xlfn.XLOOKUP("Migrate_Insecure",'Scoring_Config'!$A:$A,'Scoring_Config'!$D:$D,"Yes")="Yes",_xlfn.XLOOKUP("Migrate_Insecure",'Scoring_Config'!$A:$A,'Scoring_Config'!$C:$C,15),0),"False,0")} -> 0 | AY3: {=IF(FALSE,"True," & IF(_xlfn.XLOOKUP("Migrate_Other_Ports",'Scoring_Config'!$A:$A,'Scoring_Config'!$D:$D,"Yes")="Yes",_xlfn.XLOOKUP("Migrate_Other_Ports",'Scoring_Config'!$A:$A,'Scoring_Config'!$C:$C,5),0),"False,0")} -> 0 | AZ3: {=IF(LEFT(AU3,4)="True",0,(IF(LEFT(AC3,4)="True",IF(_xlfn.XLOOKUP("Src_IsAny",'Scoring_Config'!$A:$A,'Scoring_Config'!$D:$D,"Yes")="Yes",_xlfn.XLOOKUP("Src_IsAny",'Scoring_Config'!$A:$A,'Scoring_Config'!$C:$C,25),0),0)+IF(LEFT(AD3,4)="True",IF(_xlfn.XLOOKUP("Src_CIDR_Le_16",'Scoring_Config'!$A:$A,'Scoring_Config'!$D:$D,"Yes")="Yes",_xlfn.XLOOKUP("Src_CIDR_Le_16",'Scoring_Config'!$A:$A,'Scoring_Config'!$C:$C,25),0),0)+IF(LEFT(AE3,4)="True",IF(_xlfn.XLOOKUP("Src_CIDR_17_22",'Scoring_Config'!$A:$A,'Scoring_Config'!$D:$D,"Yes")="Yes",_xlfn.XLOOKUP("Src_CIDR_17_22",'Scoring_Config'!$A:$A,'Scoring_Config'!$C:$C,15),0),0)+IF(LEFT(AF3,4)="True",IF(_xlfn.XLOOKUP("Dst_IsAny",'Scoring_Config'!$A:$A,'Scoring_Config'!$D:$D,"Yes")="Yes",_xlfn.XLOOKUP("Dst_IsAny",'Scoring_Config'!$A:$A,'Scoring_Config'!$C:$C,25),0),0)+IF(LEFT(AG3,4)="True",IF(_xlfn.XLOOKUP("Dst_CIDR_Le_16",'Scoring_Config'!$A:$A,'Scoring_Config'!$D:$D,"Yes")="Yes",_xlfn.XLOOKUP("Dst_CIDR_Le_16",'Scoring_Config'!$A:$A,'Scoring_Config'!$C:$C,25),0),0)+IF(LEFT(AH3,4)="True",IF(_xlfn.XLOOKUP("Dst_CIDR_17_22",'Scoring_Config'!$A:$A,'Scoring_Config'!$D:$D,"Yes")="Yes",_xlfn.XLOOKUP("Dst_CIDR_17_22",'Scoring_Config'!$A:$A,'Scoring_Config'!$C:$C,15),0),0)+IF(LEFT(AI3,4)="True",IF(_xlfn.XLOOKUP("SrcZone_IsAny",'Scoring_Config'!$A:$A,'Scoring_Config'!$D:$D,"Yes")="Yes",_xlfn.XLOOKUP("SrcZone_IsAny",'Scoring_Config'!$A:$A,'Scoring_Config'!$C:$C,5),0),0)+IF(LEFT(AJ3,4)="True",IF(_xlfn.XLOOKUP("DstZone_IsAny",'Scoring_Config'!$A:$A,'Scoring_Config'!$D:$D,"Yes")="Yes",_xlfn.XLOOKUP("DstZone_IsAny",'Scoring_Config'!$A:$A,'Scoring_Config'!$C:$C,5),0),0)+IF(LEFT(AK3,4)="True",IF(_xlfn.XLOOKUP("Service_Any_OR_RangeGt1000",'Scoring_Config'!$A:$A,'Scoring_Config'!$D:$D,"Yes")="Yes",_xlfn.XLOOKUP("Service_Any_OR_RangeGt1000",'Scoring_Config'!$A:$A,'Scoring_Config'!$C:$C,25),0),0)+IF(LEFT(AL3,4)="True",IF(_xlfn.XLOOKUP("App_Any_OR_RangeGt1000",'Scoring_Config'!$A:$A,'Scoring_Config'!$D:$D,"Yes")="Yes",_xlfn.XLOOKUP("App_Any_OR_RangeGt1000",'Scoring_Config'!$A:$A,'Scoring_Config'!$C:$C,25),0),0)+IF(LEFT(AM3,4)="True",IF(_xlfn.XLOOKUP("Service_Insecure_Match",'Scoring_Config'!$A:$A,'Scoring_Config'!$D:$D,"Yes")="Yes",_xlfn.XLOOKUP("Service_Insecure_Match",'Scoring_Config'!$A:$A,'Scoring_Config'!$C:$C,20),0),0)+IF(LEFT(AN3,4)="True",IF(_xlfn.XLOOKUP("Risky_Inbound",'Scoring_Config'!$A:$A,'Scoring_Config'!$D:$D,"Yes")="Yes",_xlfn.XLOOKUP("Risky_Inbound",'Scoring_Config'!$A:$A,'Scoring_Config'!$C:$C,20),0),0)+IF(LEFT(AO3,4)="True",IF(_xlfn.XLOOKUP("Risky_Outbound",'Scoring_Config'!$A:$A,'Scoring_Config'!$D:$D,"Yes")="Yes",_xlfn.XLOOKUP("Risky_Outbound",'Scoring_Config'!$A:$A,'Scoring_Config'!$C:$C,10),0),0)+IF(LEFT(AW3,4)="True",IF(_xlfn.XLOOKUP("Migrate_Insecure",'Scoring_Config'!$A:$A,'Scoring_Config'!$D:$D,"Yes")="Yes",_xlfn.XLOOKUP("Migrate_Insecure",'Scoring_Config'!$A:$A,'Scoring_Config'!$C:$C,15),0),0)+IF(LEFT(AY3,4)="True",IF(_xlfn.XLOOKUP("Migrate_Other_Ports",'Scoring_Config'!$A:$A,'Scoring_Config'!$D:$D,"Yes")="Yes",_xlfn.XLOOKUP("Migrate_Other_Ports",'Scoring_Config'!$A:$A,'Scoring_Config'!$C:$C,5),0),0)+IF(_xlfn.XLOOKUP("Rule_Usage_Scoring",'Scoring_Config'!$A:$A,'Scoring_Config'!$D:$D,"Yes")="Yes",VALUE(MID(AP3,FIND(",",AP3)+1,100)),0)+IF(LEFT(AQ3,4)="True",IF(_xlfn.XLOOKUP("Rule_Usage_Description_Scoring",'Scoring_Config'!$A:$A,'Scoring_Config'!$D:$D,"Yes")="Yes",_xlfn.XLOOKUP("Rule_Usage_Description_Scoring",'Scoring_Config'!$A:$A,'Scoring_Config'!$C:$C,5),0),0)+IF(_xlfn.XLOOKUP("Source_User_Scoring",'Scoring_Config'!$A:$A,'Scoring_Config'!$D:$D,"Yes")="Yes",VALUE(MID(AR3,FIND(",",AR3)+1,100)),0)+IF(_xlfn.XLOOKUP("Profile_Scoring",'Scoring_Config'!$A:$A,'Scoring_Config'!$D:$D,"Yes")="Yes",VALUE(MID(AS3,FIND(",",AS3)+1,100)),0)+IF(_xlfn.XLOOKUP("Options_Scoring",'Scoring_Config'!$A:$A,'Scoring_Config'!$D:$D,"Yes")="Yes",VALUE(MID(AT3,FIND(",",AT3)+1,100)),0)))} -> 0
A4: DC_Policies_Export.csv | B4: Allow_Guest_to_DMZ_FTP | C4: la-datacenterfw | E4: universal | F4: Guest | G4: LA_All_Addresses | H4: 10.1.1.0/24; 10.1.2.0/24; 10.1.3.0/24; 10.1.4.0/24; 10.1.5.0/24; 10.1.6.0/24; 10.1.7.0/24; 10.1.9.0/24; 10.11.186.18/32; 10.114.92.22/32; 10.121.205.16/32; 10.125.9.17/32; 10.132.57.10-10.205.119.50; 10.134.26.11/32; 10.139.246.13/32; 10.141.126.23/32; 10.156.103.14/32; 10.170.252.10/32; 10.188.179.19/32; 10.189.74.21/32; 10.191.16.20/32; 10.215.129.28/32; 10.251.126.26/32; 10.253.36.12/32; 10.27.61.15/32; 10.6.235.24/32; 10.81.174.25/32; 10.9.208.29/32; 10.99.210.27/32; any; db.la.corp.local; legacy.la.corp; telemetry.la.iot; updates.la.vendor.local | I4: any | J4: DMZ | K4: any | L4: any | M4: imap | N4: 143,tcp | O4: LA_FTP_All | P4: TCP/20; TCP/21; TCP/20-21 | Q4: allow | R4: best-practice | S4: none | T4: 0 | U4: Legacy rule—owner unknown | V4: ftp, smb | W4: 68 | X4: 2025-05-06 16:14:58 | Y4: 2024-05-13 16:14:58 | AC4: {=IF(TRUE,"True," & IF(_xlfn.XLOOKUP("Src_IsAny",'Scoring_Config'!$A:$A,'Scoring_Config'!$D:$D,"Yes")="Yes",_xlfn.XLOOKUP("Src_IsAny",'Scoring_Config'!$A:$A,'Scoring_Config'!$C:$C,25),0),"False,0")} -> 0 | AD4: {=IF(FALSE,"True," & IF(_xlfn.XLOOKUP("Src_CIDR_Le_16",'Scoring_Config'!$A:$A,'Scoring_Config'!$D:$D,"Yes")="Yes",_xlfn.XLOOKUP("Src_CIDR_Le_16",'Scoring_Config'!$A:$A,'Scoring_Config'!$C:$C,25),0),"False,0")} -> 0 | AE4: {=IF(FALSE,"True," & IF(_xlfn.XLOOKUP("Src_CIDR_17_22",'Scoring_Config'!$A:$A,'Scoring_Config'!$D:$D,"Yes")="Yes",_xlfn.XLOOKUP("Src_CIDR_17_22",'Scoring_Config'!$A:$A,'Scoring_Config'!$C:$C,15),0),"False,0")} -> 0 | AF4: {=IF(TRUE,"True," & IF(_xlfn.XLOOKUP("Dst_IsAny",'Scoring_Config'!$A:$A,'Scoring_Config'!$D:$D,"Yes")="Yes",_xlfn.XLOOKUP("Dst_IsAny",'Scoring_Config'!$A:$A,'Scoring_Config'!$C:$C,25),0),"False,0")} -> 0 | AG4: {=IF(FALSE,"True," & IF(_xlfn.XLOOKUP("Dst_CIDR_Le_16",'Scoring_Config'!$A:$A,'Scoring_Config'!$D:$D,"Yes")="Yes",_xlfn.XLOOKUP("Dst_CIDR_Le_16",'Scoring_Config'!$A:$A,'Scoring_Config'!$C:$C,25),0),"False,0")} -> 0 | AH4: {=IF(FALSE,"True," & IF(_xlfn.XLOOKUP("Dst_CIDR_17_22",'Scoring_Config'!$A:$A,'Scoring_Config'!$D:$D,"Yes")="Yes",_xlfn.XLOOKUP("Dst_CIDR_17_22",'Scoring_Config'!$A:$A,'Scoring_Config'!$C:$C,15),0),"False,0")} -> 0 | AI4: {=IF(FALSE,"True," & IF(_xlfn.XLOOKUP("SrcZone_IsAny",'Scoring_Config'!$A:$A,'Scoring_Config'!$D:$D,"Yes")="Yes",_xlfn.XLOOKUP("SrcZone_IsAny",'Scoring_Config'!$A:$A,'Scoring_Config'!$C:$C,5),0),"False,0")} -> 0 | AJ4: {=IF(FALSE,"True," & IF(_xlfn.XLOOKUP("DstZone_IsAny",'Scoring_Config'!$A:$A,'Scoring_Config'!$D:$D,"Yes")="Yes",_xlfn.XLOOKUP("DstZone_IsAny",'Scoring_Config'!$A:$A,'Scoring_Config'!$C:$C,5),0),"False,0")} -> 0 | AK4: {=IF(FALSE,"True," & IF(_xlfn.XLOOKUP("Service_Any_OR_RangeGt1000",'Scoring_Config'!$A:$A,'Scoring_Config'!$D:$D,"Yes")="Yes",_xlfn.XLOOKUP("Service_Any_OR_RangeGt1000",'Scoring_Config'!$A:$A,'Scoring_Config'!$C:$C,25),0),"False,0")} -> 0 | AL4: {=IF(FALSE,"True," & IF(_xlfn.XLOOKUP("App_Any_OR_RangeGt1000",'Scoring_Config'!$A:$A,'Scoring_Config'!$D:$D,"Yes")="Yes",_xlfn.XLOOKUP("App_Any_OR_RangeGt1000",'Scoring_Config'!$A:$A,'Scoring_Config'!$C:$C,25),0),"False,0")} -> 0 | AM4: {=IF(TRUE,"True," & IF(_xlfn.XLOOKUP("Service_Insecure_Match",'Scoring_Config'!$A:$A,'Scoring_Config'!$D:$D,"Yes")="Yes",_xlfn.XLOOKUP("Service_Insecure_Match",'Scoring_Config'!$A:$A,'Scoring_Config'!$C:$C,20),0),"False,0")} -> 0 | AN4: {=IF(FALSE,"True," & IF(_xlfn.XLOOKUP("Risky_Inbound",'Scoring_Config'!$A:$A,'Scoring_Config'!$D:$D,"Yes")="Yes",_xlfn.XLOOKUP("Risky_Inbound",'Scoring_Config'!$A:$A,'Scoring_Config'!$C:$C,20),0),"False,0")} -> 0 | AO4: {=IF(FALSE,"True," & IF(_xlfn.XLOOKUP("Risky_Outbound",'Scoring_Config'!$A:$A,'Scoring_Config'!$D:$D,"Yes")="Yes",_xlfn.XLOOKUP("Risky_Outbound",'Scoring_Config'!$A:$A,'Scoring_Config'!$C:$C,10),0),"False,0")} -> 0 | AP4: True,5 | AQ4: {=IF(TRUE,"True," & IF(_xlfn.XLOOKUP("Rule_Usage_Description_Scoring",'Scoring_Config'!$A:$A,'Scoring_Config'!$D:$D,"Yes")="Yes",_xlfn.XLOOKUP("Rule_Usage_Description_Scoring",'Scoring_Config'!$A:$A,'Scoring_Config'!$C:$C,5),0),"False,0")} -> 0 | AR4: False,0 | AS4: False,0 | AT4: True,5 | AU4: {=IF(FALSE,"True," & IF(_xlfn.XLOOKUP("Action_IsDenyOrDrop",'Scoring_Config'!$A:$A,'Scoring_Config'!$D:$D,"Yes")="Yes",_xlfn.XLOOKUP("Action_IsDenyOrDrop",'Scoring_Config'!$A:$A,'Scoring_Config'!$C:$C,0),0),"False,0")} -> 0 | AW4: {=IF(FALSE,"True," & IF(_xlfn.XLOOKUP("Migrate_Insecure",'Scoring_Config'!$A:$A,'Scoring_Config'!$D:$D,"Yes")="Yes",_xlfn.XLOOKUP("Migrate_Insecure",'Scoring_Config'!$A:$A,'Scoring_Config'!$C:$C,15),0),"False,0")} -> 0 | AY4: {=IF(FALSE,"True," & IF(_xlfn.XLOOKUP("Migrate_Other_Ports",'Scoring_Config'!$A:$A,'Scoring_Config'!$D:$D,"Yes")="Yes",_xlfn.XLOOKUP("Migrate_Other_Ports",'Scoring_Config'!$A:$A,'Scoring_Config'!$C:$C,5),0),"False,0")} -> 0 | AZ4: {=IF(LEFT(AU4,4)="True",0,(IF(LEFT(AC4,4)="True",IF(_xlfn.XLOOKUP("Src_IsAny",'Scoring_Config'!$A:$A,'Scoring_Config'!$D:$D,"Yes")="Yes",_xlfn.XLOOKUP("Src_IsAny",'Scoring_Config'!$A:$A,'Scoring_Config'!$C:$C,25),0),0)+IF(LEFT(AD4,4)="True",IF(_xlfn.XLOOKUP("Src_CIDR_Le_16",'Scoring_Config'!$A:$A,'Scoring_Config'!$D:$D,"Yes")="Yes",_xlfn.XLOOKUP("Src_CIDR_Le_16",'Scoring_Config'!$A:$A,'Scoring_Config'!$C:$C,25),0),0)+IF(LEFT(AE4,4)="True",IF(_xlfn.XLOOKUP("Src_CIDR_17_22",'Scoring_Config'!$A:$A,'Scoring_Config'!$D:$D,"Yes")="Yes",_xlfn.XLOOKUP("Src_CIDR_17_22",'Scoring_Config'!$A:$A,'Scoring_Config'!$C:$C,15),0),0)+IF(LEFT(AF4,4)="True",IF(_xlfn.XLOOKUP("Dst_IsAny",'Scoring_Config'!$A:$A,'Scoring_Config'!$D:$D,"Yes")="Yes",_xlfn.XLOOKUP("Dst_IsAny",'Scoring_Config'!$A:$A,'Scoring_Config'!$C:$C,25),0),0)+IF(LEFT(AG4,4)="True",IF(_xlfn.XLOOKUP("Dst_CIDR_Le_16",'Scoring_Config'!$A:$A,'Scoring_Config'!$D:$D,"Yes")="Yes",_xlfn.XLOOKUP("Dst_CIDR_Le_16",'Scoring_Config'!$A:$A,'Scoring_Config'!$C:$C,25),0),0)+IF(LEFT(AH4,4)="True",IF(_xlfn.XLOOKUP("Dst_CIDR_17_22",'Scoring_Config'!$A:$A,'Scoring_Config'!$D:$D,"Yes")="Yes",_xlfn.XLOOKUP("Dst_CIDR_17_22",'Scoring_Config'!$A:$A,'Scoring_Config'!$C:$C,15),0),0)+IF(LEFT(AI4,4)="True",IF(_xlfn.XLOOKUP("SrcZone_IsAny",'Scoring_Config'!$A:$A,'Scoring_Config'!$D:$D,"Yes")="Yes",_xlfn.XLOOKUP("SrcZone_IsAny",'Scoring_Config'!$A:$A,'Scoring_Config'!$C:$C,5),0),0)+IF(LEFT(AJ4,4)="True",IF(_xlfn.XLOOKUP("DstZone_IsAny",'Scoring_Config'!$A:$A,'Scoring_Config'!$D:$D,"Yes")="Yes",_xlfn.XLOOKUP("DstZone_IsAny",'Scoring_Config'!$A:$A,'Scoring_Config'!$C:$C,5),0),0)+IF(LEFT(AK4,4)="True",IF(_xlfn.XLOOKUP("Service_Any_OR_RangeGt1000",'Scoring_Config'!$A:$A,'Scoring_Config'!$D:$D,"Yes")="Yes",_xlfn.XLOOKUP("Service_Any_OR_RangeGt1000",'Scoring_Config'!$A:$A,'Scoring_Config'!$C:$C,25),0),0)+IF(LEFT(AL4,4)="True",IF(_xlfn.XLOOKUP("App_Any_OR_RangeGt1000",'Scoring_Config'!$A:$A,'Scoring_Config'!$D:$D,"Yes")="Yes",_xlfn.XLOOKUP("App_Any_OR_RangeGt1000",'Scoring_Config'!$A:$A,'Scoring_Config'!$C:$C,25),0),0)+IF(LEFT(AM4,4)="True",IF(_xlfn.XLOOKUP("Service_Insecure_Match",'Scoring_Config'!$A:$A,'Scoring_Config'!$D:$D,"Yes")="Yes",_xlfn.XLOOKUP("Service_Insecure_Match",'Scoring_Config'!$A:$A,'Scoring_Config'!$C:$C,20),0),0)+IF(LEFT(AN4,4)="True",IF(_xlfn.XLOOKUP("Risky_Inbound",'Scoring_Config'!$A:$A,'Scoring_Config'!$D:$D,"Yes")="Yes",_xlfn.XLOOKUP("Risky_Inbound",'Scoring_Config'!$A:$A,'Scoring_Config'!$C:$C,20),0),0)+IF(LEFT(AO4,4)="True",IF(_xlfn.XLOOKUP("Risky_Outbound",'Scoring_Config'!$A:$A,'Scoring_Config'!$D:$D,"Yes")="Yes",_xlfn.XLOOKUP("Risky_Outbound",'Scoring_Config'!$A:$A,'Scoring_Config'!$C:$C,10),0),0)+IF(LEFT(AW4,4)="True",IF(_xlfn.XLOOKUP("Migrate_Insecure",'Scoring_Config'!$A:$A,'Scoring_Config'!$D:$D,"Yes")="Yes",_xlfn.XLOOKUP("Migrate_Insecure",'Scoring_Config'!$A:$A,'Scoring_Config'!$C:$C,15),0),0)+IF(LEFT(AY4,4)="True",IF(_xlfn.XLOOKUP("Migrate_Other_Ports",'Scoring_Config'!$A:$A,'Scoring_Config'!$D:$D,"Yes")="Yes",_xlfn.XLOOKUP("Migrate_Other_Ports",'Scoring_Config'!$A:$A,'Scoring_Config'!$C:$C,5),0),0)+IF(_xlfn.XLOOKUP("Rule_Usage_Scoring",'Scoring_Config'!$A:$A,'Scoring_Config'!$D:$D,"Yes")="Yes",VALUE(MID(AP4,FIND(",",AP4)+1,100)),0)+IF(LEFT(AQ4,4)="True",IF(_xlfn.XLOOKUP("Rule_Usage_Description_Scoring",'Scoring_Config'!$A:$A,'Scoring_Config'!$D:$D,"Yes")="Yes",_xlfn.XLOOKUP("Rule_Usage_Description_Scoring",'Scoring_Config'!$A:$A,'Scoring_Config'!$C:$C,5),0),0)+IF(_xlfn.XLOOKUP("Source_User_Scoring",'Scoring_Config'!$A:$A,'Scoring_Config'!$D:$D,"Yes")="Yes",VALUE(MID(AR4,FIND(",",AR4)+1,100)),0)+IF(_xlfn.XLOOKUP("Profile_Scoring",'Scoring_Config'!$A:$A,'Scoring_Config'!$D:$D,"Yes")="Yes",VALUE(MID(AS4,FIND(",",AS4)+1,100)),0)+IF(_xlfn.XLOOKUP("Options_Scoring",'Scoring_Config'!$A:$A,'Scoring_Config'!$D:$D,"Yes")="Yes",VALUE(MID(AT4,FIND(",",AT4)+1,100)),0)))} -> 0
A5: DC_Policies_Export.csv | B5: Allow_Mgmt_to_Mgmt_DNS | C5: la-datacenterfw | E5: universal | F5: Mgmt | G5: legacy.la.corp | H5: legacy.la.corp | I5: domain\itops | J5: Mgmt | K5: any | L5: any | M5: dns | N5: dns | O5: LA_Windows_RPC_NetBIOS | P5: TCP/135; UDP/135; TCP/137; UDP/137; TCP/139; UDP/139 | Q5: allow | R5: best-practice | S5: Traffic log sent at session end | T5: 145 | U5: Temporary allow per INC540876 (expires in 30d) | V5: (none) | W5: 95 | X5: 2025-09-13 21:21:58 | Y5: 2025-07-12 21:21:58 | AC5: {=IF(FALSE,"True," & IF(_xlfn.XLOOKUP("Src_IsAny",'Scoring_Config'!$A:$A,'Scoring_Config'!$D:$D,"Yes")="Yes",_xlfn.XLOOKUP("Src_IsAny",'Scoring_Config'!$A:$A,'Scoring_Config'!$C:$C,25),0),"False,0")} -> 0 | AD5: {=IF(FALSE,"True," & IF(_xlfn.XLOOKUP("Src_CIDR_Le_16",'Scoring_Config'!$A:$A,'Scoring_Config'!$D:$D,"Yes")="Yes",_xlfn.XLOOKUP("Src_CIDR_Le_16",'Scoring_Config'!$A:$A,'Scoring_Config'!$C:$C,25),0),"False,0")} -> 0 | AE5: {=IF(FALSE,"True," & IF(_xlfn.XLOOKUP("Src_CIDR_17_22",'Scoring_Config'!$A:$A,'Scoring_Config'!$D:$D,"Yes")="Yes",_xlfn.XLOOKUP("Src_CIDR_17_22",'Scoring_Config'!$A:$A,'Scoring_Config'!$C:$C,15),0),"False,0")} -> 0 | AF5: {=IF(TRUE,"True," & IF(_xlfn.XLOOKUP("Dst_IsAny",'Scoring_Config'!$A:$A,'Scoring_Config'!$D:$D,"Yes")="Yes",_xlfn.XLOOKUP("Dst_IsAny",'Scoring_Config'!$A:$A,'Scoring_Config'!$C:$C,25),0),"False,0")} -> 0 | AG5: {=IF(FALSE,"True," & IF(_xlfn.XLOOKUP("Dst_CIDR_Le_16",'Scoring_Config'!$A:$A,'Scoring_Config'!$D:$D,"Yes")="Yes",_xlfn.XLOOKUP("Dst_CIDR_Le_16",'Scoring_Config'!$A:$A,'Scoring_Config'!$C:$C,25),0),"False,0")} -> 0 | AH5: {=IF(FALSE,"True," & IF(_xlfn.XLOOKUP("Dst_CIDR_17_22",'Scoring_Config'!$A:$A,'Scoring_Config'!$D:$D,"Yes")="Yes",_xlfn.XLOOKUP("Dst_CIDR_17_22",'Scoring_Config'!$A:$A,'Scoring_Config'!$C:$C,15),0),"False,0")} -> 0 | AI5: {=IF(FALSE,"True," & IF(_xlfn.XLOOKUP("SrcZone_IsAny",'Scoring_Config'!$A:$A,'Scoring_Config'!$D:$D,"Yes")="Yes",_xlfn.XLOOKUP("SrcZone_IsAny",'Scoring_Config'!$A:$A,'Scoring_Config'!$C:$C,5),0),"False,0")} -> 0 | AJ5: {=IF(FALSE,"True," & IF(_xlfn.XLOOKUP("DstZone_IsAny",'Scoring_Config'!$A:$A,'Scoring_Config'!$D:$D,"Yes")="Yes",_xlfn.XLOOKUP("DstZone_IsAny",'Scoring_Config'!$A:$A,'Scoring_Config'!$C:$C,5),0),"False,0")} -> 0 | AK5: {=IF(FALSE,"True," & IF(_xlfn.XLOOKUP("Service_Any_OR_RangeGt1000",'Scoring_Config'!$A:$A,'Scoring_Config'!$D:$D,"Yes")="Yes",_xlfn.XLOOKUP("Service_Any_OR_RangeGt1000",'Scoring_Config'!$A:$A,'Scoring_Config'!$C:$C,25),0),"False,0")} -> 0 | AL5: {=IF(FALSE,"True," & IF(_xlfn.XLOOKUP("App_Any_OR_RangeGt1000",'Scoring_Config'!$A:$A,'Scoring_Config'!$D:$D,"Yes")="Yes",_xlfn.XLOOKUP("App_Any_OR_RangeGt1000",'Scoring_Config'!$A:$A,'Scoring_Config'!$C:$C,25),0),"False,0")} -> 0 | AM5: {=IF(TRUE,"True," & IF(_xlfn.XLOOKUP("Service_Insecure_Match",'Scoring_Config'!$A:$A,'Scoring_Config'!$D:$D,"Yes")="Yes",_xlfn.XLOOKUP("Service_Insecure_Match",'Scoring_Config'!$A:$A,'Scoring_Config'!$C:$C,20),0),"False,0")} -> 0 | AN5: {=IF(FALSE,"True," & IF(_xlfn.XLOOKUP("Risky_Inbound",'Scoring_Config'!$A:$A,'Scoring_Config'!$D:$D,"Yes")="Yes",_xlfn.XLOOKUP("Risky_Inbound",'Scoring_Config'!$A:$A,'Scoring_Config'!$C:$C,20),0),"False,0")} -> 0 | AO5: {=IF(FALSE,"True," & IF(_xlfn.XLOOKUP("Risky_Outbound",'Scoring_Config'!$A:$A,'Scoring_Config'!$D:$D,"Yes")="Yes",_xlfn.XLOOKUP("Risky_Outbound",'Scoring_Config'!$A:$A,'Scoring_Config'!$C:$C,10),0),"False,0")} -> 0 | AP5: True,5 | AQ5: {=IF(FALSE,"True," & IF(_xlfn.XLOOKUP("Rule_Usage_Description_Scoring",'Scoring_Config'!$A:$A,'Scoring_Config'!$D:$D,"Yes")="Yes",_xlfn.XLOOKUP("Rule_Usage_Description_Scoring",'Scoring_Config'!$A:$A,'Scoring_Config'!$C:$C,5),0),"False,0")} -> 0 | AR5: True,-10 | AS5: False,0 | AT5: False,0 | AU5: {=IF(FALSE,"True," & IF(_xlfn.XLOOKUP("Action_IsDenyOrDrop",'Scoring_Config'!$A:$A,'Scoring_Config'!$D:$D,"Yes")="Yes",_xlfn.XLOOKUP("Action_IsDenyOrDrop",'Scoring_Config'!$A:$A,'Scoring_Config'!$C:$C,0),0),"False,0")} -> 0 | AW5: {=IF(FALSE,"True," & IF(_xlfn.XLOOKUP("Migrate_Insecure",'Scoring_Config'!$A:$A,'Scoring_Config'!$D:$D,"Yes")="Yes",_xlfn.XLOOKUP("Migrate_Insecure",'Scoring_Config'!$A:$A,'Scoring_Config'!$C:$C,15),0),"False,0")} -> 0 | AY5: {=IF(FALSE,"True," & IF(_xlfn.XLOOKUP("Migrate_Other_Ports",'Scoring_Config'!$A:$A,'Scoring_Config'!$D:$D,"Yes")="Yes",_xlfn.XLOOKUP("Migrate_Other_Ports",'Scoring_Config'!$A:$A,'Scoring_Config'!$C:$C,5),0),"False,0")} -> 0 | AZ5: {=IF(LEFT(AU5,4)="True",0,(IF(LEFT(AC5,4)="True",IF(_xlfn.XLOOKUP("Src_IsAny",'Scoring_Config'!$A:$A,'Scoring_Config'!$D:$D,"Yes")="Yes",_xlfn.XLOOKUP("Src_IsAny",'Scoring_Config'!$A:$A,'Scoring_Config'!$C:$C,25),0),0)+IF(LEFT(AD5,4)="True",IF(_xlfn.XLOOKUP("Src_CIDR_Le_16",'Scoring_Config'!$A:$A,'Scoring_Config'!$D:$D,"Yes")="Yes",_xlfn.XLOOKUP("Src_CIDR_Le_16",'Scoring_Config'!$A:$A,'Scoring_Config'!$C:$C,25),0),0)+IF(LEFT(AE5,4)="True",IF(_xlfn.XLOOKUP("Src_CIDR_17_22",'Scoring_Config'!$A:$A,'Scoring_Config'!$D:$D,"Yes")="Yes",_xlfn.XLOOKUP("Src_CIDR_17_22",'Scoring_Config'!$A:$A,'Scoring_Config'!$C:$C,15),0),0)+IF(LEFT(AF5,4)="True",IF(_xlfn.XLOOKUP("Dst_IsAny",'Scoring_Config'!$A:$A,'Scoring_Config'!$D:$D,"Yes")="Yes",_xlfn.XLOOKUP("Dst_IsAny",'Scoring_Config'!$A:$A,'Scoring_Config'!$C:$C,25),0),0)+IF(LEFT(AG5,4)="True",IF(_xlfn.XLOOKUP("Dst_CIDR_Le_16",'Scoring_Config'!$A:$A,'Scoring_Config'!$D:$D,"Yes")="Yes",_xlfn.XLOOKUP("Dst_CIDR_Le_16",'Scoring_Config'!$A:$A,'Scoring_Config'!$C:$C,25),0),0)+IF(LEFT(AH5,4)="True",IF(_xlfn.XLOOKUP("Dst_CIDR_17_22",'Scoring_Config'!$A:$A,'Scoring_Config'!$D:$D,"Yes")="Yes",_xlfn.XLOOKUP("Dst_CIDR_17_22",'Scoring_Config'!$A:$A,'Scoring_Config'!$C:$C,15),0),0)+IF(LEFT(AI5,4)="True",IF(_xlfn.XLOOKUP("SrcZone_IsAny",'Scoring_Config'!$A:$A,'Scoring_Config'!$D:$D,"Yes")="Yes",_xlfn.XLOOKUP("SrcZone_IsAny",'Scoring_Config'!$A:$A,'Scoring_Config'!$C:$C,5),0),0)+IF(LEFT(AJ5,4)="True",IF(_xlfn.XLOOKUP("DstZone_IsAny",'Scoring_Config'!$A:$A,'Scoring_Config'!$D:$D,"Yes")="Yes",_xlfn.XLOOKUP("DstZone_IsAny",'Scoring_Config'!$A:$A,'Scoring_Config'!$C:$C,5),0),0)+IF(LEFT(AK5,4)="True",IF(_xlfn.XLOOKUP("Service_Any_OR_RangeGt1000",'Scoring_Config'!$A:$A,'Scoring_Config'!$D:$D,"Yes")="Yes",_xlfn.XLOOKUP("Service_Any_OR_RangeGt1000",'Scoring_Config'!$A:$A,'Scoring_Config'!$C:$C,25),0),0)+IF(LEFT(AL5,4)="True",IF(_xlfn.XLOOKUP("App_Any_OR_RangeGt1000",'Scoring_Config'!$A:$A,'Scoring_Config'!$D:$D,"Yes")="Yes",_xlfn.XLOOKUP("App_Any_OR_RangeGt1000",'Scoring_Config'!$A:$A,'Scoring_Config'!$C:$C,25),0),0)+IF(LEFT(AM5,4)="True",IF(_xlfn.XLOOKUP("Service_Insecure_Match",'Scoring_Config'!$A:$A,'Scoring_Config'!$D:$D,"Yes")="Yes",_xlfn.XLOOKUP("Service_Insecure_Match",'Scoring_Config'!$A:$A,'Scoring_Config'!$C:$C,20),0),0)+IF(LEFT(AN5,4)="True",IF(_xlfn.XLOOKUP("Risky_Inbound",'Scoring_Config'!$A:$A,'Scoring_Config'!$D:$D,"Yes")="Yes",_xlfn.XLOOKUP("Risky_Inbound",'Scoring_Config'!$A:$A,'Scoring_Config'!$C:$C,20),0),0)+IF(LEFT(AO5,4)="True",IF(_xlfn.XLOOKUP("Risky_Outbound",'Scoring_Config'!$A:$A,'Scoring_Config'!$D:$D,"Yes")="Yes",_xlfn.XLOOKUP("Risky_Outbound",'Scoring_Config'!$A:$A,'Scoring_Config'!$C:$C,10),0),0)+IF(LEFT(AW5,4)="True",IF(_xlfn.XLOOKUP("Migrate_Insecure",'Scoring_Config'!$A:$A,'Scoring_Config'!$D:$D,"Yes")="Yes",_xlfn.XLOOKUP("Migrate_Insecure",'Scoring_Config'!$A:$A,'Scoring_Config'!$C:$C,15),0),0)+IF(LEFT(AY5,4)="True",IF(_xlfn.XLOOKUP("Migrate_Other_Ports",'Scoring_Config'!$A:$A,'Scoring_Config'!$D:$D,"Yes")="Yes",_xlfn.XLOOKUP("Migrate_Other_Ports",'Scoring_Config'!$A:$A,'Scoring_Config'!$C:$C,5),0),0)+IF(_xlfn.XLOOKUP("Rule_Usage_Scoring",'Scoring_Config'!$A:$A,'Scoring_Config'!$D:$D,"Yes")="Yes",VALUE(MID(AP5,FIND(",",AP5)+1,100)),0)+IF(LEFT(AQ5,4)="True",IF(_xlfn.XLOOKUP("Rule_Usage_Description_Scoring",'Scoring_Config'!$A:$A,'Scoring_Config'!$D:$D,"Yes")="Yes",_xlfn.XLOOKUP("Rule_Usage_Description_Scoring",'Scoring_Config'!$A:$A,'Scoring_Config'!$C:$C,5),0),0)+IF(_xlfn.XLOOKUP("Source_User_Scoring",'Scoring_Config'!$A:$A,'Scoring_Config'!$D:$D,"Yes")="Yes",VALUE(MID(AR5,FIND(",",AR5)+1,100)),0)+IF(_xlfn.XLOOKUP("Profile_Scoring",'Scoring_Config'!$A:$A,'Scoring_Config'!$D:$D,"Yes")="Yes",VALUE(MID(AS5,FIND(",",AS5)+1,100)),0)+IF(_xlfn.XLOOKUP("Options_Scoring",'Scoring_Config'!$A:$A,'Scoring_Config'!$D:$D,"Yes")="Yes",VALUE(MID(AT5,FIND(",",AT5)+1,100)),0)))} -> 0
A6: DC_Policies_Export.csv | B6: Allow_Internet_to_DMZ_IMAP | C6: la-datacenterfw | E6: universal | F6: Untrust | G6: any | H6: any | I6: svc_batch | J6: DMZ | K6: 10.216.162.24/32 | L6: 10.216.162.24/32 | M6: imap | N6: 143,tcp | O6: LA_SNMP_Group | P6: TCP/161; UDP/161 | Q6: allow | R6: antivirus | S6: Traffic log sent at session end; Log Forwarding Profile setting: Forward to Panorama | T6: 0 | U6: Temporary workaround—no ticket provided | V6: ssh | W6: 166 | X6: 2025-07-28 04:56:58 | Y6: 2023-12-01 04:56:58 | AC6: {=IF(TRUE,"True," & IF(_xlfn.XLOOKUP("Src_IsAny",'Scoring_Config'!$A:$A,'Scoring_Config'!$D:$D,"Yes")="Yes",_xlfn.XLOOKUP("Src_IsAny",'Scoring_Config'!$A:$A,'Scoring_Config'!$C:$C,25),0),"False,0")} -> 0 | AD6: {=IF(FALSE,"True," & IF(_xlfn.XLOOKUP("Src_CIDR_Le_16",'Scoring_Config'!$A:$A,'Scoring_Config'!$D:$D,"Yes")="Yes",_xlfn.XLOOKUP("Src_CIDR_Le_16",'Scoring_Config'!$A:$A,'Scoring_Config'!$C:$C,25),0),"False,0")} -> 0 | AE6: {=IF(FALSE,"True," & IF(_xlfn.XLOOKUP("Src_CIDR_17_22",'Scoring_Config'!$A:$A,'Scoring_Config'!$D:$D,"Yes")="Yes",_xlfn.XLOOKUP("Src_CIDR_17_22",'Scoring_Config'!$A:$A,'Scoring_Config'!$C:$C,15),0),"False,0")} -> 0 | AF6: {=IF(FALSE,"True," & IF(_xlfn.XLOOKUP("Dst_IsAny",'Scoring_Config'!$A:$A,'Scoring_Config'!$D:$D,"Yes")="Yes",_xlfn.XLOOKUP("Dst_IsAny",'Scoring_Config'!$A:$A,'Scoring_Config'!$C:$C,25),0),"False,0")} -> 0 | AG6: {=IF(FALSE,"True," & IF(_xlfn.XLOOKUP("Dst_CIDR_Le_16",'Scoring_Config'!$A:$A,'Scoring_Config'!$D:$D,"Yes")="Yes",_xlfn.XLOOKUP("Dst_CIDR_Le_16",'Scoring_Config'!$A:$A,'Scoring_Config'!$C:$C,25),0),"False,0")} -> 0 | AH6: {=IF(FALSE,"True," & IF(_xlfn.XLOOKUP("Dst_CIDR_17_22",'Scoring_Config'!$A:$A,'Scoring_Config'!$D:$D,"Yes")="Yes",_xlfn.XLOOKUP("Dst_CIDR_17_22",'Scoring_Config'!$A:$A,'Scoring_Config'!$C:$C,15),0),"False,0")} -> 0 | AI6: {=IF(FALSE,"True," & IF(_xlfn.XLOOKUP("SrcZone_IsAny",'Scoring_Config'!$A:$A,'Scoring_Config'!$D:$D,"Yes")="Yes",_xlfn.XLOOKUP("SrcZone_IsAny",'Scoring_Config'!$A:$A,'Scoring_Config'!$C:$C,5),0),"False,0")} -> 0 | AJ6: {=IF(FALSE,"True," & IF(_xlfn.XLOOKUP("DstZone_IsAny",'Scoring_Config'!$A:$A,'Scoring_Config'!$D:$D,"Yes")="Yes",_xlfn.XLOOKUP("DstZone_IsAny",'Scoring_Config'!$A:$A,'Scoring_Config'!$C:$C,5),0),"False,0")} -> 0 | AK6: {=IF(FALSE,"True," & IF(_xlfn.XLOOKUP("Service_Any_OR_RangeGt1000",'Scoring_Config'!$A:$A,'Scoring_Config'!$D:$D,"Yes")="Yes",_xlfn.XLOOKUP("Service_Any_OR_RangeGt1000",'Scoring_Config'!$A:$A,'Scoring_Config'!$C:$C,25),0),"False,0")} -> 0 | AL6: {=IF(FALSE,"True," & IF(_xlfn.XLOOKUP("App_Any_OR_RangeGt1000",'Scoring_Config'!$A:$A,'Scoring_Config'!$D:$D,"Yes")="Yes",_xlfn.XLOOKUP("App_Any_OR_RangeGt1000",'Scoring_Config'!$A:$A,'Scoring_Config'!$C:$C,25),0),"False,0")} -> 0 | AM6: {=IF(TRUE,"True," & IF(_xlfn.XLOOKUP("Service_Insecure_Match",'Scoring_Config'!$A:$A,'Scoring_Config'!$D:$D,"Yes")="Yes",_xlfn.XLOOKUP("Service_Insecure_Match",'Scoring_Config'!$A:$A,'Scoring_Config'!$C:$C,20),0),"False,0")} -> 0 | AN6: {=IF(FALSE,"True," & IF(_xlfn.XLOOKUP("Risky_Inbound",'Scoring_Config'!$A:$A,'Scoring_Config'!$D:$D,"Yes")="Yes",_xlfn.XLOOKUP("Risky_Inbound",'Scoring_Config'!$A:$A,'Scoring_Config'!$C:$C,20),0),"False,0")} -> 0 | AO6: {=IF(FALSE,"True," & IF(_xlfn.XLOOKUP("Risky_Outbound",'Scoring_Config'!$A:$A,'Scoring_Config'!$D:$D,"Yes")="Yes",_xlfn.XLOOKUP("Risky_Outbound",'Scoring_Config'!$A:$A,'Scoring_Config'!$C:$C,10),0),"False,0")} -> 0 | AP6: True,5 | AQ6: {=IF(TRUE,"True," & IF(_xlfn.XLOOKUP("Rule_Usage_Description_Scoring",'Scoring_Config'!$A:$A,'Scoring_Config'!$D:$D,"Yes")="Yes",_xlfn.XLOOKUP("Rule_Usage_Description_Scoring",'Scoring_Config'!$A:$A,'Scoring_Config'!$C:$C,5),0),"False,0")} -> 0 | AR6: True,-10 | AS6: False,0 | AT6: False,0 | AU6: {=IF(FALSE,"True," & IF(_xlfn.XLOOKUP("Action_IsDenyOrDrop",'Scoring_Config'!$A:$A,'Scoring_Config'!$D:$D,"Yes")="Yes",_xlfn.XLOOKUP("Action_IsDenyOrDrop",'Scoring_Config'!$A:$A,'Scoring_Config'!$C:$C,0),0),"False,0")} -> 0 | AW6: {=IF(FALSE,"True," & IF(_xlfn.XLOOKUP("Migrate_Insecure",'Scoring_Config'!$A:$A,'Scoring_Config'!$D:$D,"Yes")="Yes",_xlfn.XLOOKUP("Migrate_Insecure",'Scoring_Config'!$A:$A,'Scoring_Config'!$C:$C,15),0),"False,0")} -> 0 | AY6: {=IF(FALSE,"True," & IF(_xlfn.XLOOKUP("Migrate_Other_Ports",'Scoring_Config'!$A:$A,'Scoring_Config'!$D:$D,"Yes")="Yes",_xlfn.XLOOKUP("Migrate_Other_Ports",'Scoring_Config'!$A:$A,'Scoring_Config'!$C:$C,5),0),"False,0")} -> 0 | AZ6: {=IF(LEFT(AU6,4)="True",0,(IF(LEFT(AC6,4)="True",IF(_xlfn.XLOOKUP("Src_IsAny",'Scoring_Config'!$A:$A,'Scoring_Config'!$D:$D,"Yes")="Yes",_xlfn.XLOOKUP("Src_IsAny",'Scoring_Config'!$A:$A,'Scoring_Config'!$C:$C,25),0),0)+IF(LEFT(AD6,4)="True",IF(_xlfn.XLOOKUP("Src_CIDR_Le_16",'Scoring_Config'!$A:$A,'Scoring_Config'!$D:$D,"Yes")="Yes",_xlfn.XLOOKUP("Src_CIDR_Le_16",'Scoring_Config'!$A:$A,'Scoring_Config'!$C:$C,25),0),0)+IF(LEFT(AE6,4)="True",IF(_xlfn.XLOOKUP("Src_CIDR_17_22",'Scoring_Config'!$A:$A,'Scoring_Config'!$D:$D,"Yes")="Yes",_xlfn.XLOOKUP("Src_CIDR_17_22",'Scoring_Config'!$A:$A,'Scoring_Config'!$C:$C,15),0),0)+IF(LEFT(AF6,4)="True",IF(_xlfn.XLOOKUP("Dst_IsAny",'Scoring_Config'!$A:$A,'Scoring_Config'!$D:$D,"Yes")="Yes",_xlfn.XLOOKUP("Dst_IsAny",'Scoring_Config'!$A:$A,'Scoring_Config'!$C:$C,25),0),0)+IF(LEFT(AG6,4)="True",IF(_xlfn.XLOOKUP("Dst_CIDR_Le_16",'Scoring_Config'!$A:$A,'Scoring_Config'!$D:$D,"Yes")="Yes",_xlfn.XLOOKUP("Dst_CIDR_Le_16",'Scoring_Config'!$A:$A,'Scoring_Config'!$C:$C,25),0),0)+IF(LEFT(AH6,4)="True",IF(_xlfn.XLOOKUP("Dst_CIDR_17_22",'Scoring_Config'!$A:$A,'Scoring_Config'!$D:$D,"Yes")="Yes",_xlfn.XLOOKUP("Dst_CIDR_17_22",'Scoring_Config'!$A:$A,'Scoring_Config'!$C:$C,15),0),0)+IF(LEFT(AI6,4)="True",IF(_xlfn.XLOOKUP("SrcZone_IsAny",'Scoring_Config'!$A:$A,'Scoring_Config'!$D:$D,"Yes")="Yes",_xlfn.XLOOKUP("SrcZone_IsAny",'Scoring_Config'!$A:$A,'Scoring_Config'!$C:$C,5),0),0)+IF(LEFT(AJ6,4)="True",IF(_xlfn.XLOOKUP("DstZone_IsAny",'Scoring_Config'!$A:$A,'Scoring_Config'!$D:$D,"Yes")="Yes",_xlfn.XLOOKUP("DstZone_IsAny",'Scoring_Config'!$A:$A,'Scoring_Config'!$C:$C,5),0),0)+IF(LEFT(AK6,4)="True",IF(_xlfn.XLOOKUP("Service_Any_OR_RangeGt1000",'Scoring_Config'!$A:$A,'Scoring_Config'!$D:$D,"Yes")="Yes",_xlfn.XLOOKUP("Service_Any_OR_RangeGt1000",'Scoring_Config'!$A:$A,'Scoring_Config'!$C:$C,25),0),0)+IF(LEFT(AL6,4)="True",IF(_xlfn.XLOOKUP("App_Any_OR_RangeGt1000",'Scoring_Config'!$A:$A,'Scoring_Config'!$D:$D,"Yes")="Yes",_xlfn.XLOOKUP("App_Any_OR_RangeGt1000",'Scoring_Config'!$A:$A,'Scoring_Config'!$C:$C,25),0),0)+IF(LEFT(AM6,4)="True",IF(_xlfn.XLOOKUP("Service_Insecure_Match",'Scoring_Config'!$A:$A,'Scoring_Config'!$D:$D,"Yes")="Yes",_xlfn.XLOOKUP("Service_Insecure_Match",'Scoring_Config'!$A:$A,'Scoring_Config'!$C:$C,20),0),0)+IF(LEFT(AN6,4)="True",IF(_xlfn.XLOOKUP("Risky_Inbound",'Scoring_Config'!$A:$A,'Scoring_Config'!$D:$D,"Yes")="Yes",_xlfn.XLOOKUP("Risky_Inbound",'Scoring_Config'!$A:$A,'Scoring_Config'!$C:$C,20),0),0)+IF(LEFT(AO6,4)="True",IF(_xlfn.XLOOKUP("Risky_Outbound",'Scoring_Config'!$A:$A,'Scoring_Config'!$D:$D,"Yes")="Yes",_xlfn.XLOOKUP("Risky_Outbound",'Scoring_Config'!$A:$A,'Scoring_Config'!$C:$C,10),0),0)+IF(LEFT(AW6,4)="True",IF(_xlfn.XLOOKUP("Migrate_Insecure",'Scoring_Config'!$A:$A,'Scoring_Config'!$D:$D,"Yes")="Yes",_xlfn.XLOOKUP("Migrate_Insecure",'Scoring_Config'!$A:$A,'Scoring_Config'!$C:$C,15),0),0)+IF(LEFT(AY6,4)="True",IF(_xlfn.XLOOKUP("Migrate_Other_Ports",'Scoring_Config'!$A:$A,'Scoring_Config'!$D:$D,"Yes")="Yes",_xlfn.XLOOKUP("Migrate_Other_Ports",'Scoring_Config'!$A:$A,'Scoring_Config'!$C:$C,5),0),0)+IF(_xlfn.XLOOKUP("Rule_Usage_Scoring",'Scoring_Config'!$A:$A,'Scoring_Config'!$D:$D,"Yes")="Yes",VALUE(MID(AP6,FIND(",",AP6)+1,100)),0)+IF(LEFT(AQ6,4)="True",IF(_xlfn.XLOOKUP("Rule_Usage_Description_Scoring",'Scoring_Config'!$A:$A,'Scoring_Config'!$D:$D,"Yes")="Yes",_xlfn.XLOOKUP("Rule_Usage_Description_Scoring",'Scoring_Config'!$A:$A,'Scoring_Config'!$C:$C,5),0),0)+IF(_xlfn.XLOOKUP("Source_User_Scoring",'Scoring_Config'!$A:$A,'Scoring_Config'!$D:$D,"Yes")="Yes",VALUE(MID(AR6,FIND(",",AR6)+1,100)),0)+IF(_xlfn.XLOOKUP("Profile_Scoring",'Scoring_Config'!$A:$A,'Scoring_Config'!$D:$D,"Yes")="Yes",VALUE(MID(AS6,FIND(",",AS6)+1,100)),0)+IF(_xlfn.XLOOKUP("Options_Scoring",'Scoring_Config'!$A:$A,'Scoring_Config'!$D:$D,"Yes")="Yes",VALUE(MID(AT6,FIND(",",AT6)+1,100)),0)))} -> 0
A7: DC_Policies_Export.csv | B7: Allow_DMZ_to_DMZ_POP3 | C7: la-datacenterfw | E7: universal | F7: DMZ | G7: srv-la-app05.corp.local | H7: 10.156.103.14/32 | I7: any | J7: DMZ | K7: 10.1.5.0/24 | L7: 10.1.5.0/24 | M7: pop3 | N7: 110,tcp | O7: netbios-ns-udp-137 | P7: UDP/137 | Q7: allow | R7: best-practice | S7: log at both ends | T7: 171 | U7: Change approved under INC779751 | V7: ftp, smb | W7: 374 | X7: 2025-05-28 03:05:58 | Y7: 2023-11-23 03:05:58 | AC7: {=IF(FALSE,"True," & IF(_xlfn.XLOOKUP("Src_IsAny",'Scoring_Config'!$A:$A,'Scoring_Config'!$D:$D,"Yes")="Yes",_xlfn.XLOOKUP("Src_IsAny",'Scoring_Config'!$A:$A,'Scoring_Config'!$C:$C,25),0),"False,0")} -> 0 | AD7: {=IF(FALSE,"True," & IF(_xlfn.XLOOKUP("Src_CIDR_Le_16",'Scoring_Config'!$A:$A,'Scoring_Config'!$D:$D,"Yes")="Yes",_xlfn.XLOOKUP("Src_CIDR_Le_16",'Scoring_Config'!$A:$A,'Scoring_Config'!$C:$C,25),0),"False,0")} -> 0 | AE7: {=IF(FALSE,"True," & IF(_xlfn.XLOOKUP("Src_CIDR_17_22",'Scoring_Config'!$A:$A,'Scoring_Config'!$D:$D,"Yes")="Yes",_xlfn.XLOOKUP("Src_CIDR_17_22",'Scoring_Config'!$A:$A,'Scoring_Config'!$C:$C,15),0),"False,0")} -> 0 | AF7: {=IF(FALSE,"True," & IF(_xlfn.XLOOKUP("Dst_IsAny",'Scoring_Config'!$A:$A,'Scoring_Config'!$D:$D,"Yes")="Yes",_xlfn.XLOOKUP("Dst_IsAny",'Scoring_Config'!$A:$A,'Scoring_Config'!$C:$C,25),0),"False,0")} -> 0 | AG7: {=IF(FALSE,"True," & IF(_xlfn.XLOOKUP("Dst_CIDR_Le_16",'Scoring_Config'!$A:$A,'Scoring_Config'!$D:$D,"Yes")="Yes",_xlfn.XLOOKUP("Dst_CIDR_Le_16",'Scoring_Config'!$A:$A,'Scoring_Config'!$C:$C,25),0),"False,0")} -> 0 | AH7: {=IF(FALSE,"True," & IF(_xlfn.XLOOKUP("Dst_CIDR_17_22",'Scoring_Config'!$A:$A,'Scoring_Config'!$D:$D,"Yes")="Yes",_xlfn.XLOOKUP("Dst_CIDR_17_22",'Scoring_Config'!$A:$A,'Scoring_Config'!$C:$C,15),0),"False,0")} -> 0 | AI7: {=IF(FALSE,"True," & IF(_xlfn.XLOOKUP("SrcZone_IsAny",'Scoring_Config'!$A:$A,'Scoring_Config'!$D:$D,"Yes")="Yes",_xlfn.XLOOKUP("SrcZone_IsAny",'Scoring_Config'!$A:$A,'Scoring_Config'!$C:$C,5),0),"False,0")} -> 0 | AJ7: {=IF(FALSE,"True," & IF(_xlfn.XLOOKUP("DstZone_IsAny",'Scoring_Config'!$A:$A,'Scoring_Config'!$D:$D,"Yes")="Yes",_xlfn.XLOOKUP("DstZone_IsAny",'Scoring_Config'!$A:$A,'Scoring_Config'!$C:$C,5),0),"False,0")} -> 0 | AK7: {=IF(FALSE,"True," & IF(_xlfn.XLOOKUP("Service_Any_OR_RangeGt1000",'Scoring_Config'!$A:$A,'Scoring_Config'!$D:$D,"Yes")="Yes",_xlfn.XLOOKUP("Service_Any_OR_RangeGt1000",'Scoring_Config'!$A:$A,'Scoring_Config'!$C:$C,25),0),"False,0")} -> 0 | AL7: {=IF(FALSE,"True," & IF(_xlfn.XLOOKUP("App_Any_OR_RangeGt1000",'Scoring_Config'!$A:$A,'Scoring_Config'!$D:$D,"Yes")="Yes",_xlfn.XLOOKUP("App_Any_OR_RangeGt1000",'Scoring_Config'!$A:$A,'Scoring_Config'!$C:$C,25),0),"False,0")} -> 0 | AM7: {=IF(TRUE,"True," & IF(_xlfn.XLOOKUP("Service_Insecure_Match",'Scoring_Config'!$A:$A,'Scoring_Config'!$D:$D,"Yes")="Yes",_xlfn.XLOOKUP("Service_Insecure_Match",'Scoring_Config'!$A:$A,'Scoring_Config'!$C:$C,20),0),"False,0")} -> 0 | AN7: {=IF(FALSE,"True," & IF(_xlfn.XLOOKUP("Risky_Inbound",'Scoring_Config'!$A:$A,'Scoring_Config'!$D:$D,"Yes")="Yes",_xlfn.XLOOKUP("Risky_Inbound",'Scoring_Config'!$A:$A,'Scoring_Config'!$C:$C,20),0),"False,0")} -> 0 | AO7: {=IF(FALSE,"True," & IF(_xlfn.XLOOKUP("Risky_Outbound",'Scoring_Config'!$A:$A,'Scoring_Config'!$D:$D,"Yes")="Yes",_xlfn.XLOOKUP("Risky_Outbound",'Scoring_Config'!$A:$A,'Scoring_Config'!$C:$C,10),0),"False,0")} -> 0 | AP7: True,5 | AQ7: {=IF(FALSE,"True," & IF(_xlfn.XLOOKUP("Rule_Usage_Description_Scoring",'Scoring_Config'!$A:$A,'Scoring_Config'!$D:$D,"Yes")="Yes",_xlfn.XLOOKUP("Rule_Usage_Description_Scoring",'Scoring_Config'!$A:$A,'Scoring_Config'!$C:$C,5),0),"False,0")} -> 0 | AR7: False,0 | AS7: False,0 | AT7: False,0 | AU7: {=IF(FALSE,"True," & IF(_xlfn.XLOOKUP("Action_IsDenyOrDrop",'Scoring_Config'!$A:$A,'Scoring_Config'!$D:$D,"Yes")="Yes",_xlfn.XLOOKUP("Action_IsDenyOrDrop",'Scoring_Config'!$A:$A,'Scoring_Config'!$C:$C,0),0),"False,0")} -> 0 | AW7: {=IF(FALSE,"True," & IF(_xlfn.XLOOKUP("Migrate_Insecure",'Scoring_Config'!$A:$A,'Scoring_Config'!$D:$D,"Yes")="Yes",_xlfn.XLOOKUP("Migrate_Insecure",'Scoring_Config'!$A:$A,'Scoring_Config'!$C:$C,15),0),"False,0")} -> 0 | AY7: {=IF(FALSE,"True," & IF(_xlfn.XLOOKUP("Migrate_Other_Ports",'Scoring_Config'!$A:$A,'Scoring_Config'!$D:$D,"Yes")="Yes",_xlfn.XLOOKUP("Migrate_Other_Ports",'Scoring_Config'!$A:$A,'Scoring_Config'!$C:$C,5),0),"False,0")} -> 0 | AZ7: {=IF(LEFT(AU7,4)="True",0,(IF(LEFT(AC7,4)="True",IF(_xlfn.XLOOKUP("Src_IsAny",'Scoring_Config'!$A:$A,'Scoring_Config'!$D:$D,"Yes")="Yes",_xlfn.XLOOKUP("Src_IsAny",'Scoring_Config'!$A:$A,'Scoring_Config'!$C:$C,25),0),0)+IF(LEFT(AD7,4)="True",IF(_xlfn.XLOOKUP("Src_CIDR_Le_16",'Scoring_Config'!$A:$A,'Scoring_Config'!$D:$D,"Yes")="Yes",_xlfn.XLOOKUP("Src_CIDR_Le_16",'Scoring_Config'!$A:$A,'Scoring_Config'!$C:$C,25),0),0)+IF(LEFT(AE7,4)="True",IF(_xlfn.XLOOKUP("Src_CIDR_17_22",'Scoring_Config'!$A:$A,'Scoring_Config'!$D:$D,"Yes")="Yes",_xlfn.XLOOKUP("Src_CIDR_17_22",'Scoring_Config'!$A:$A,'Scoring_Config'!$C:$C,15),0),0)+IF(LEFT(AF7,4)="True",IF(_xlfn.XLOOKUP("Dst_IsAny",'Scoring_Config'!$A:$A,'Scoring_Config'!$D:$D,"Yes")="Yes",_xlfn.XLOOKUP("Dst_IsAny",'Scoring_Config'!$A:$A,'Scoring_Config'!$C:$C,25),0),0)+IF(LEFT(AG7,4)="True",IF(_xlfn.XLOOKUP("Dst_CIDR_Le_16",'Scoring_Config'!$A:$A,'Scoring_Config'!$D:$D,"Yes")="Yes",_xlfn.XLOOKUP("Dst_CIDR_Le_16",'Scoring_Config'!$A:$A,'Scoring_Config'!$C:$C,25),0),0)+IF(LEFT(AH7,4)="True",IF(_xlfn.XLOOKUP("Dst_CIDR_17_22",'Scoring_Config'!$A:$A,'Scoring_Config'!$D:$D,"Yes")="Yes",_xlfn.XLOOKUP("Dst_CIDR_17_22",'Scoring_Config'!$A:$A,'Scoring_Config'!$C:$C,15),0),0)+IF(LEFT(AI7,4)="True",IF(_xlfn.XLOOKUP("SrcZone_IsAny",'Scoring_Config'!$A:$A,'Scoring_Config'!$D:$D,"Yes")="Yes",_xlfn.XLOOKUP("SrcZone_IsAny",'Scoring_Config'!$A:$A,'Scoring_Config'!$C:$C,5),0),0)+IF(LEFT(AJ7,4)="True",IF(_xlfn.XLOOKUP("DstZone_IsAny",'Scoring_Config'!$A:$A,'Scoring_Config'!$D:$D,"Yes")="Yes",_xlfn.XLOOKUP("DstZone_IsAny",'Scoring_Config'!$A:$A,'Scoring_Config'!$C:$C,5),0),0)+IF(LEFT(AK7,4)="True",IF(_xlfn.XLOOKUP("Service_Any_OR_RangeGt1000",'Scoring_Config'!$A:$A,'Scoring_Config'!$D:$D,"Yes")="Yes",_xlfn.XLOOKUP("Service_Any_OR_RangeGt1000",'Scoring_Config'!$A:$A,'Scoring_Config'!$C:$C,25),0),0)+IF(LEFT(AL7,4)="True",IF(_xlfn.XLOOKUP("App_Any_OR_RangeGt1000",'Scoring_Config'!$A:$A,'Scoring_Config'!$D:$D,"Yes")="Yes",_xlfn.XLOOKUP("App_Any_OR_RangeGt1000",'Scoring_Config'!$A:$A,'Scoring_Config'!$C:$C,25),0),0)+IF(LEFT(AM7,4)="True",IF(_xlfn.XLOOKUP("Service_Insecure_Match",'Scoring_Config'!$A:$A,'Scoring_Config'!$D:$D,"Yes")="Yes",_xlfn.XLOOKUP("Service_Insecure_Match",'Scoring_Config'!$A:$A,'Scoring_Config'!$C:$C,20),0),0)+IF(LEFT(AN7,4)="True",IF(_xlfn.XLOOKUP("Risky_Inbound",'Scoring_Config'!$A:$A,'Scoring_Config'!$D:$D,"Yes")="Yes",_xlfn.XLOOKUP("Risky_Inbound",'Scoring_Config'!$A:$A,'Scoring_Config'!$C:$C,20),0),0)+IF(LEFT(AO7,4)="True",IF(_xlfn.XLOOKUP("Risky_Outbound",'Scoring_Config'!$A:$A,'Scoring_Config'!$D:$D,"Yes")="Yes",_xlfn.XLOOKUP("Risky_Outbound",'Scoring_Config'!$A:$A,'Scoring_Config'!$C:$C,10),0),0)+IF(LEFT(AW7,4)="True",IF(_xlfn.XLOOKUP("Migrate_Insecure",'Scoring_Config'!$A:$A,'Scoring_Config'!$D:$D,"Yes")="Yes",_xlfn.XLOOKUP("Migrate_Insecure",'Scoring_Config'!$A:$A,'Scoring_Config'!$C:$C,15),0),0)+IF(LEFT(AY7,4)="True",IF(_xlfn.XLOOKUP("Migrate_Other_Ports",'Scoring_Config'!$A:$A,'Scoring_Config'!$D:$D,"Yes")="Yes",_xlfn.XLOOKUP("Migrate_Other_Ports",'Scoring_Config'!$A:$A,'Scoring_Config'!$C:$C,5),0),0)+IF(_xlfn.XLOOKUP("Rule_Usage_Scoring",'Scoring_Config'!$A:$A,'Scoring_Config'!$D:$D,"Yes")="Yes",VALUE(MID(AP7,FIND(",",AP7)+1,100)),0)+IF(LEFT(AQ7,4)="True",IF(_xlfn.XLOOKUP("Rule_Usage_Description_Scoring",'Scoring_Config'!$A:$A,'Scoring_Config'!$D:$D,"Yes")="Yes",_xlfn.XLOOKUP("Rule_Usage_Description_Scoring",'Scoring_Config'!$A:$A,'Scoring_Config'!$C:$C,5),0),0)+IF(_xlfn.XLOOKUP("Source_User_Scoring",'Scoring_Config'!$A:$A,'Scoring_Config'!$D:$D,"Yes")="Yes",VALUE(MID(AR7,FIND(",",AR7)+1,100)),0)+IF(_xlfn.XLOOKUP("Profile_Scoring",'Scoring_Config'!$A:$A,'Scoring_Config'!$D:$D,"Yes")="Yes",VALUE(MID(AS7,FIND(",",AS7)+1,100)),0)+IF(_xlfn.XLOOKUP("Options_Scoring",'Scoring_Config'!$A:$A,'Scoring_Config'!$D:$D,"Yes")="Yes",VALUE(MID(AT7,FIND(",",AT7)+1,100)),0)))} -> 0
A8: DC_Policies_Export.csv | B8: Allow_Internet_to_Mgmt_DNS | C8: la-datacenterfw | E8: universal | F8: Untrust | G8: any | H8: any | I8: svc_backup | J8: Trust | K8: any | L8: any | M8: any | N8: any | O8: ms-rpc-udp-135 | P8: UDP/135 | Q8: allow | R8: none | S8: Traffic log sent at start | T8: 8325 | U8: Temporary workaround—no ticket provided | V8: ssh | W8: 252 | X8: 2025-08-04 05:23:58 | Y8: 2023-03-12 05:23:58 | AC8: {=IF(TRUE,"True," & IF(_xlfn.XLOOKUP("Src_IsAny",'Scoring_Config'!$A:$A,'Scoring_Config'!$D:$D,"Yes")="Yes",_xlfn.XLOOKUP("Src_IsAny",'Scoring_Config'!$A:$A,'Scoring_Config'!$C:$C,25),0),"False,0")} -> 0 | AD8: {=IF(FALSE,"True," & IF(_xlfn.XLOOKUP("Src_CIDR_Le_16",'Scoring_Config'!$A:$A,'Scoring_Config'!$D:$D,"Yes")="Yes",_xlfn.XLOOKUP("Src_CIDR_Le_16",'Scoring_Config'!$A:$A,'Scoring_Config'!$C:$C,25),0),"False,0")} -> 0 | AE8: {=IF(FALSE,"True," & IF(_xlfn.XLOOKUP("Src_CIDR_17_22",'Scoring_Config'!$A:$A,'Scoring_Config'!$D:$D,"Yes")="Yes",_xlfn.XLOOKUP("Src_CIDR_17_22",'Scoring_Config'!$A:$A,'Scoring_Config'!$C:$C,15),0),"False,0")} -> 0 | AF8: {=IF(TRUE,"True," & IF(_xlfn.XLOOKUP("Dst_IsAny",'Scoring_Config'!$A:$A,'Scoring_Config'!$D:$D,"Yes")="Yes",_xlfn.XLOOKUP("Dst_IsAny",'Scoring_Config'!$A:$A,'Scoring_Config'!$C:$C,25),0),"False,0")} -> 0 | AG8: {=IF(FALSE,"True," & IF(_xlfn.XLOOKUP("Dst_CIDR_Le_16",'Scoring_Config'!$A:$A,'Scoring_Config'!$D:$D,"Yes")="Yes",_xlfn.XLOOKUP("Dst_CIDR_Le_16",'Scoring_Config'!$A:$A,'Scoring_Config'!$C:$C,25),0),"False,0")} -> 0 | AH8: {=IF(FALSE,"True," & IF(_xlfn.XLOOKUP("Dst_CIDR_17_22",'Scoring_Config'!$A:$A,'Scoring_Config'!$D:$D,"Yes")="Yes",_xlfn.XLOOKUP("Dst_CIDR_17_22",'Scoring_Config'!$A:$A,'Scoring_Config'!$C:$C,15),0),"False,0")} -> 0 | AI8: {=IF(FALSE,"True," & IF(_xlfn.XLOOKUP("SrcZone_IsAny",'Scoring_Config'!$A:$A,'Scoring_Config'!$D:$D,"Yes")="Yes",_xlfn.XLOOKUP("SrcZone_IsAny",'Scoring_Config'!$A:$A,'Scoring_Config'!$C:$C,5),0),"False,0")} -> 0 | AJ8: {=IF(FALSE,"True," & IF(_xlfn.XLOOKUP("DstZone_IsAny",'Scoring_Config'!$A:$A,'Scoring_Config'!$D:$D,"Yes")="Yes",_xlfn.XLOOKUP("DstZone_IsAny",'Scoring_Config'!$A:$A,'Scoring_Config'!$C:$C,5),0),"False,0")} -> 0 | AK8: {=IF(FALSE,"True," & IF(_xlfn.XLOOKUP("Service_Any_OR_RangeGt1000",'Scoring_Config'!$A:$A,'Scoring_Config'!$D:$D,"Yes")="Yes",_xlfn.XLOOKUP("Service_Any_OR_RangeGt1000",'Scoring_Config'!$A:$A,'Scoring_Config'!$C:$C,25),0),"False,0")} -> 0 | AL8: {=IF(TRUE,"True," & IF(_xlfn.XLOOKUP("App_Any_OR_RangeGt1000",'Scoring_Config'!$A:$A,'Scoring_Config'!$D:$D,"Yes")="Yes",_xlfn.XLOOKUP("App_Any_OR_RangeGt1000",'Scoring_Config'!$A:$A,'Scoring_Config'!$C:$C,25),0),"False,0")} -> 0 | AM8: {=IF(TRUE,"True," & IF(_xlfn.XLOOKUP("Service_Insecure_Match",'Scoring_Config'!$A:$A,'Scoring_Config'!$D:$D,"Yes")="Yes",_xlfn.XLOOKUP("Service_Insecure_Match",'Scoring_Config'!$A:$A,'Scoring_Config'!$C:$C,20),0),"False,0")} -> 0 | AN8: {=IF(FALSE,"True," & IF(_xlfn.XLOOKUP("Risky_Inbound",'Scoring_Config'!$A:$A,'Scoring_Config'!$D:$D,"Yes")="Yes",_xlfn.XLOOKUP("Risky_Inbound",'Scoring_Config'!$A:$A,'Scoring_Config'!$C:$C,20),0),"False,0")} -> 0 | AO8: {=IF(FALSE,"True," & IF(_xlfn.XLOOKUP("Risky_Outbound",'Scoring_Config'!$A:$A,'Scoring_Config'!$D:$D,"Yes")="Yes",_xlfn.XLOOKUP("Risky_Outbound",'Scoring_Config'!$A:$A,'Scoring_Config'!$C:$C,10),0),"False,0")} -> 0 | AP8: True,5 | AQ8: {=IF(TRUE,"True," & IF(_xlfn.XLOOKUP("Rule_Usage_Description_Scoring",'Scoring_Config'!$A:$A,'Scoring_Config'!$D:$D,"Yes")="Yes",_xlfn.XLOOKUP("Rule_Usage_Description_Scoring",'Scoring_Config'!$A:$A,'Scoring_Config'!$C:$C,5),0),"False,0")} -> 0 | AR8: True,-10 | AS8: True,5 | AT8: False,0 | AU8: {=IF(FALSE,"True," & IF(_xlfn.XLOOKUP("Action_IsDenyOrDrop",'Scoring_Config'!$A:$A,'Scoring_Config'!$D:$D,"Yes")="Yes",_xlfn.XLOOKUP("Action_IsDenyOrDrop",'Scoring_Config'!$A:$A,'Scoring_Config'!$C:$C,0),0),"False,0")} -> 0 | AW8: {=IF(FALSE,"True," & IF(_xlfn.XLOOKUP("Migrate_Insecure",'Scoring_Config'!$A:$A,'Scoring_Config'!$D:$D,"Yes")="Yes",_xlfn.XLOOKUP("Migrate_Insecure",'Scoring_Config'!$A:$A,'Scoring_Config'!$C:$C,15),0),"False,0")} -> 0 | AY8: {=IF(FALSE,"True," & IF(_xlfn.XLOOKUP("Migrate_Other_Ports",'Scoring_Config'!$A:$A,'Scoring_Config'!$D:$D,"Yes")="Yes",_xlfn.XLOOKUP("Migrate_Other_Ports",'Scoring_Config'!$A:$A,'Scoring_Config'!$C:$C,5),0),"False,0")} -> 0 | AZ8: {=IF(LEFT(AU8,4)="True",0,(IF(LEFT(AC8,4)="True",IF(_xlfn.XLOOKUP("Src_IsAny",'Scoring_Config'!$A:$A,'Scoring_Config'!$D:$D,"Yes")="Yes",_xlfn.XLOOKUP("Src_IsAny",'Scoring_Config'!$A:$A,'Scoring_Config'!$C:$C,25),0),0)+IF(LEFT(AD8,4)="True",IF(_xlfn.XLOOKUP("Src_CIDR_Le_16",'Scoring_Config'!$A:$A,'Scoring_Config'!$D:$D,"Yes")="Yes",_xlfn.XLOOKUP("Src_CIDR_Le_16",'Scoring_Config'!$A:$A,'Scoring_Config'!$C:$C,25),0),0)+IF(LEFT(AE8,4)="True",IF(_xlfn.XLOOKUP("Src_CIDR_17_22",'Scoring_Config'!$A:$A,'Scoring_Config'!$D:$D,"Yes")="Yes",_xlfn.XLOOKUP("Src_CIDR_17_22",'Scoring_Config'!$A:$A,'Scoring_Config'!$C:$C,15),0),0)+IF(LEFT(AF8,4)="True",IF(_xlfn.XLOOKUP("Dst_IsAny",'Scoring_Config'!$A:$A,'Scoring_Config'!$D:$D,"Yes")="Yes",_xlfn.XLOOKUP("Dst_IsAny",'Scoring_Config'!$A:$A,'Scoring_Config'!$C:$C,25),0),0)+IF(LEFT(AG8,4)="True",IF(_xlfn.XLOOKUP("Dst_CIDR_Le_16",'Scoring_Config'!$A:$A,'Scoring_Config'!$D:$D,"Yes")="Yes",_xlfn.XLOOKUP("Dst_CIDR_Le_16",'Scoring_Config'!$A:$A,'Scoring_Config'!$C:$C,25),0),0)+IF(LEFT(AH8,4)="True",IF(_xlfn.XLOOKUP("Dst_CIDR_17_22",'Scoring_Config'!$A:$A,'Scoring_Config'!$D:$D,"Yes")="Yes",_xlfn.XLOOKUP("Dst_CIDR_17_22",'Scoring_Config'!$A:$A,'Scoring_Config'!$C:$C,15),0),0)+IF(LEFT(AI8,4)="True",IF(_xlfn.XLOOKUP("SrcZone_IsAny",'Scoring_Config'!$A:$A,'Scoring_Config'!$D:$D,"Yes")="Yes",_xlfn.XLOOKUP("SrcZone_IsAny",'Scoring_Config'!$A:$A,'Scoring_Config'!$C:$C,5),0),0)+IF(LEFT(AJ8,4)="True",IF(_xlfn.XLOOKUP("DstZone_IsAny",'Scoring_Config'!$A:$A,'Scoring_Config'!$D:$D,"Yes")="Yes",_xlfn.XLOOKUP("DstZone_IsAny",'Scoring_Config'!$A:$A,'Scoring_Config'!$C:$C,5),0),0)+IF(LEFT(AK8,4)="True",IF(_xlfn.XLOOKUP("Service_Any_OR_RangeGt1000",'Scoring_Config'!$A:$A,'Scoring_Config'!$D:$D,"Yes")="Yes",_xlfn.XLOOKUP("Service_Any_OR_RangeGt1000",'Scoring_Config'!$A:$A,'Scoring_Config'!$C:$C,25),0),0)+IF(LEFT(AL8,4)="True",IF(_xlfn.XLOOKUP("App_Any_OR_RangeGt1000",'Scoring_Config'!$A:$A,'Scoring_Config'!$D:$D,"Yes")="Yes",_xlfn.XLOOKUP("App_Any_OR_RangeGt1000",'Scoring_Config'!$A:$A,'Scoring_Config'!$C:$C,25),0),0)+IF(LEFT(AM8,4)="True",IF(_xlfn.XLOOKUP("Service_Insecure_Match",'Scoring_Config'!$A:$A,'Scoring_Config'!$D:$D,"Yes")="Yes",_xlfn.XLOOKUP("Service_Insecure_Match",'Scoring_Config'!$A:$A,'Scoring_Config'!$C:$C,20),0),0)+IF(LEFT(AN8,4)="True",IF(_xlfn.XLOOKUP("Risky_Inbound",'Scoring_Config'!$A:$A,'Scoring_Config'!$D:$D,"Yes")="Yes",_xlfn.XLOOKUP("Risky_Inbound",'Scoring_Config'!$A:$A,'Scoring_Config'!$C:$C,20),0),0)+IF(LEFT(AO8,4)="True",IF(_xlfn.XLOOKUP("Risky_Outbound",'Scoring_Config'!$A:$A,'Scoring_Config'!$D:$D,"Yes")="Yes",_xlfn.XLOOKUP("Risky_Outbound",'Scoring_Config'!$A:$A,'Scoring_Config'!$C:$C,10),0),0)+IF(LEFT(AW8,4)="True",IF(_xlfn.XLOOKUP("Migrate_Insecure",'Scoring_Config'!$A:$A,'Scoring_Config'!$D:$D,"Yes")="Yes",_xlfn.XLOOKUP("Migrate_Insecure",'Scoring_Config'!$A:$A,'Scoring_Config'!$C:$C,15),0),0)+IF(LEFT(AY8,4)="True",IF(_xlfn.XLOOKUP("Migrate_Other_Ports",'Scoring_Config'!$A:$A,'Scoring_Config'!$D:$D,"Yes")="Yes",_xlfn.XLOOKUP("Migrate_Other_Ports",'Scoring_Config'!$A:$A,'Scoring_Config'!$C:$C,5),0),0)+IF(_xlfn.XLOOKUP("Rule_Usage_Scoring",'Scoring_Config'!$A:$A,'Scoring_Config'!$D:$D,"Yes")="Yes",VALUE(MID(AP8,FIND(",",AP8)+1,100)),0)+IF(LEFT(AQ8,4)="True",IF(_xlfn.XLOOKUP("Rule_Usage_Description_Scoring",'Scoring_Config'!$A:$A,'Scoring_Config'!$D:$D,"Yes")="Yes",_xlfn.XLOOKUP("Rule_Usage_Description_Scoring",'Scoring_Config'!$A:$A,'Scoring_Config'!$C:$C,5),0),0)+IF(_xlfn.XLOOKUP("Source_User_Scoring",'Scoring_Config'!$A:$A,'Scoring_Config'!$D:$D,"Yes")="Yes",VALUE(MID(AR8,FIND(",",AR8)+1,100)),0)+IF(_xlfn.XLOOKUP("Profile_Scoring",'Scoring_Config'!$A:$A,'Scoring_Config'!$D:$D,"Yes")="Yes",VALUE(MID(AS8,FIND(",",AS8)+1,100)),0)+IF(_xlfn.XLOOKUP("Options_Scoring",'Scoring_Config'!$A:$A,'Scoring_Config'!$D:$D,"Yes")="Yes",VALUE(MID(AT8,FIND(",",AT8)+1,100)),0)))} -> 0
